Workbook

Sheet Cover
A1: NEXCORT IQ
A2: INTERNAL PRICING GUIDE — CONFIDENTIAL
A3: Intelligence at the Speed of Response
A6: HOW TO USE THIS GUIDE
A7: Public-facing language: | B7: "Tailored deployment" · "Custom quote" · "Scaled for agency needs" · "Contact sales"
A8: Internal pricing basis: | B8: Agency size · Dispatcher seats · PSAPs / sites · Call volume · CAD complexity · Security requirements · Add-ons · Support level
A9: Color convention: | B9: Blue text = hardcoded input (editable) · Green text = Included · Grey = Limited · Red = Add-on
A10: Discounting: | B10: See Discounting Rules tab — Sales Director approval required for >15% discount
A11: CAD write-back rule: | B11: Do NOT include full CAD write-back in pilot base pricing — scope separately after discovery
A12: Catalog date: October 2026 — aligned to live addon-catalog + RFP 2396IP Venue Security Dept rates (Javits)
A13: SHEET INDEX
A14: Sheet | B14: Description
A15: 1. Essential Plan | B15: Base subscription, overage, capabilities for small agencies
A16: 2. Professional Plan | B16: Growing counties/cities, full feature set, QA included
A17: 3. Command Plan | B17: Large agencies, command center, up to 75 seats
A18: 4. Enterprise & Statewide | B18: Multi-agency, 50–500+ seats, custom programs
A19: 5. CAD Integration | B19: Discovery → coordination → read-only → write-back tiers
A20: 6. AI & Call Intelligence | B20: Triage, confidence scoring, summarization, custom tuning
A21: 7. Transcription & Translation | B21: Enhanced accuracy, diarization, live translation, language packs
A22: 8. Caller Media | B22: SMS, photo upload, video upload, live streaming, redaction
A23: 9. Supervisor & QA | B23: Scorecards, coaching, dashboards, QA rubrics
A24: 10. Incident Command | B24: War rooms, command dashboards, runbooks, stakeholder pages
A25: 11. Reliability & Tech Ops | B25: Monitoring integrations, SLOs, alert correlation, on-call routing
... A32: 18. Discounting Rules | B32: Approval thresholds, discount caps, strategic guidance
A34: 19. RC Campus — Per-student annual pricing · $1.40/student/yr · min $15K
A35: 20. RC Venue — Venue & event security · capacity-based annual pricing
A36: 21. RC Hospital — Hospital & healthcare · facility-based annual pricing
A37: 22. RC Transit — Transit & transportation · fleet-based annual pricing
A38: 23. Verticals Overview — All 5 product verticals — side-by-side comparison
A39: 24. Feature Add-Ons — QR & NFC · Agency Share · NexIQ Vision™ · Call Assist · iQ Reporting · Command Intelligence · Vault · RCS · CAD Mesh · NG911 Assist
A40: 25. Sales Definitions — In-depth sales language for every sellable service / SKU | B40: Pitch, buyer, positioning, and ‘what it is not’ — no prices

Sheet Sales Definitions
A1: NEXCORT IQ — INTERNAL PRICING GUIDE
A2: SALES DEFINITIONS (Catalog date: October 2026)
A3: In-depth sales definitions for every sellable service — how to explain it, who buys it, how to position it, and what it is not. Not a technical design doc. Prices live on the other tabs; this tab is language only.
A4: HOW TO USE: Filter by Category. Use column D on calls and in proposals. Column G prevents overselling. Yellow cells on Quote Builder still hold prices — this tab is words only.
A5: Category | B5: Service / SKU | C5: One-Line Pitch | D5: Sales Definition (in depth) | E5: Who Buys This | F5: How to Sell It | G5: What It Is NOT | H5: See Sheet
A6: BASE PLANS
A7: Base Plans | B7: NexCort iQ Essential | C7: AI-assisted intake for small PSAPs without replacing CAD. | D7: Essential is the low-risk entry plan for small municipalities, single-site PSAPs, and grant-funded pilots (typically up to ~10 dispatcher seats). The agency gets the web and desktop apps, RBAC, core reporting, audit logs, AI-assisted intake, live transcription, and basic call workflows. Full dispatcher console, deep QA, and full multilingual depth stay Limited — those are the Professional upsell. Position Essential as modernization that sits beside their existing CAD and telephony, not a rip-and-replace. Recommended for first-reference customers and 90-day pilots. | E7: Small city / town PSAPs, pilot sponsors, grant-funded first deployments | F7: Lead with low commitment and grant fit. Show intake + transcription value in week one. Park CAD write-back and Command suites for later. | G7: Not a full command platform; not a CAD replacement; not full QA/translation out of the box | H7: Essential
A8: Base Plans | B8: NexCort iQ Professional | C8: Full intelligence layer for growing counties and cities — translation, QA, and analytics included. | D8: Professional is the standard production plan for growing counties and mid-size cities (typically up to ~25 dispatcher seats). It includes everything in Essential plus the full dispatcher monitoring console, live translation, caller photo/video upload, supervisor QA tools, scorecards, coaching notes, team dashboards, and incident timeline reconstruction. Priority support is included. This is the plan most agencies should land on after a successful Essential pilot. Major incident / war-room / reliability suites remain add-ons or Command upgrades. | E8: County and city ECC directors, supervisors who want QA + translation without Command complexity | F8: Sell the jump from Limited → Included: translation, QA, media, and supervisor dashboards. Use pilot results to justify the step-up. | G8: Not regional command / multi-EOC; not automatic CAD write-back; war rooms still add-on | H8: Professional
A9: Base Plans | B9: NexCort iQ Command | C9: Command and coordination platform for large agencies and major-incident environments. | D9: Command is for large agencies and regional command environments (typically up to ~75 seats) that need major-incident management, command dashboards, war rooms, runbooks, stakeholder status pages, alert correlation, escalation, on-call routing, and reliability reporting — all included. Use this when the buyer’s pain is coordination across teams and partners during storms, MCI, or large events — not just call-taking. Premium onboarding and dedicated rollout planning are included. Custom CAD connectors and dedicated support engineers remain scoped add-ons. | E9: Large PSAPs, regional centers, agencies with formal EOC / major-incident programs | F9: Lead with war rooms, runbooks, and command dashboards. Emphasize coordination value during the last big event they remember. | G9: Not Enterprise multi-agency statewide; not a free path to CAD mesh or write-back | H9: Command
A10: Base Plans | B10: NexCort iQ Enterprise / Statewide | C10: Custom multi-agency or statewide programs — priced and scoped as a program, not a menu. | D10: Enterprise covers multi-agency, statewide, or complex multi-site programs (often 50–500+ seats) with custom security reviews, multi-site deployment support, and negotiated commercial terms. Do not quote Enterprise from a simple seat calculator — engage Solutions / Sales Director early. Expect longer discovery, multiple stakeholders (state 911 boards, shared CAD vendors, IT security), and staged rollouts by agency or region. | E10: State 911 authorities, multi-jurisdiction consortia, large metro consolidations | F10: Treat as a program sale: discovery workshop → phased SOW → reference architecture. Never discount below Discounting Rules without approval. | G10: Not a self-serve SKU; not a one-week pilot package | H10: Enterprise
A11: PRODUCT VERTICALS
A12: Product Verticals | B12: RC Campus | C12: Campus safety reporting layer — QR/NFC/SMS tips without forcing an app download. | D12: RC Campus is sold to universities, colleges, and K–12 on a per-enrolled-student annual model (see Campus sheet for rate and minimums). Students and staff report via QR, NFC, or SMS; campus security gets a dedicated console — not the 911 dispatcher workspace. Base includes tip intake, two-way chat, photo/video, incident timeline, basic Clery documentation log, and campus RBAC. Upsell AI summary, advanced Clery, zone QR, NexIQ Vision™, translation, analytics, Agency Share, and SMS location. Position as the missing safety layer between ‘call 911’ and ‘ignore it.’ | E12: Campus safety directors, Clery coordinators, university IT / risk | F12: Open with ‘no app download’ and Clery documentation. Land with tip adoption; expand into Vision, Clery module, and alerts. | G12: Not a PSAP CAD console; basic Clery log is not the full Clery Act Compliance Module / legal advice | H12: RC Campus
A13: Product Verticals | B13: RC Venue | C13: Fan-to-security reporting for stadiums, arenas, and events — zone-aware, no app required. | D13: RC Venue prices by venue capacity tier (annual). Guests report from QR/NFC/SMS tied to section, gate, or zone; venue security and supervisors work an orange-branded venue console. Guest Services is a separate non-emergency console and must never be sold as 911 dispatch. Strong for event operators who already have cameras and access control but lack a guest reporting path into security. Upsell Vision cameras, live video, analytics, translation, and event-day onsite support. Also sell Venue Security Department licensing (named-seat list $2,133/user/yr or site-wide dept package) for convention-center / staff incident reporting — see RC Venue sheet (RFP 2396IP). | E13: Venue GMs, event security directors, stadium operations | F13: Demo a section-level tip into the security console. Separate Guest Services from Security in every conversation. | G13: Not a 911 ECC product; Guest Services console is not emergency dispatch | H13: RC Venue
A14: Product Verticals | B14: RC Hospital | C14: Hospital capacity and pre-alert coordination for EMS–hospital handoffs and MCI readiness. | D14: RC Hospital is facility/bed-tier annual pricing for hospitals and health systems. Hospital staff update capacity and acknowledge pre-alerts in a hospital portal — they do not sit on the PSAP dispatcher console. Base includes staff/supervisor/admin/coordinator views, pre-alert intake, and timelines. Upsell MCI command, EMS data integration, Agency Share, analytics, and Hospital Routing Module. Sell into EMS coordinators and ED leadership who need faster, cleaner pre-alerts — not into the 911 floor as a replacement console. | E14: Hospital EMS coordinators, ED leadership, health-system emergency management | F14: Lead with pre-alert acknowledgment and capacity visibility. Attach MCI module for regional readiness grants. | G14: Not a CAD; not a PSAP dispatch console; not a full EHR | H14: RC Hospital
A15: Product Verticals | B15: RC Transit | C15: Passenger-to-security reporting for bus and rail systems — vehicle and station aware. | D15: RC Transit prices by fleet/system tier (annual). Passengers report via QR/NFC/SMS; transit security and supervisors use a transit ops console. Base includes reporting channels, two-way chat, media intake, timelines, and transit RBAC. Upsell Vision cameras, Agency Share, analytics, translation, SMS location, and alerts. Position for transit authorities that need a passenger safety channel without building a mobile app. | E15: Transit authority security / safety directors, rail and bus ops leadership | F15: Show a vehicle/station tip landing in the transit console. Bundle SMS location for outdoor stops. | G15: Not a PSAP CAD; not AVL by itself (sell Map Unit Overlays separately where CAD/AVL exists) | H15: RC Transit
A16: Product Verticals | B16: Call Assist (non-emergency product) | C16: AI-assisted non-emergency call handling that keeps 911 off the non-emergency queue. | D16: Call Assist is a standalone non-emergency product: greeting flows, classification, callbacks, operator console, and supervisor monitor. Emergency 911 is never in scope — the Safety Engine transfers immediately and that path cannot be suppressed. Users land on /app/call-assist/* — never the 911 dispatcher workspace. Sell to agencies drowning in non-emergency volume who want AI help without putting automation on the 911 console. Module list price is the starting point; CAD push, RMS drafts, TTY, and external routing are optional expansions. Never free. | E16: ECC directors, non-emergency call center managers, city service line operators | F16: Quantify non-emergency volume first. Promise containment and warm transfer — never ‘AI answers 911.’ | G16: Not a 911 dispatcher console; not an unsupervised bot on emergency lines; CAD/RMS push stays human-reviewed | H16: Feature Add-Ons
A17: CAD INTEGRATION
A18: CAD Integration | B18: CAD Discovery Workshop | C18: Paid discovery that decides what CAD integration is actually possible. | D18: A structured workshop with PSAP, IT, and CAD vendor stakeholders to map fields, environments, nature codes, and write-back risk. Sell this before promising any CAD connectivity. Basic / Standard / Advanced tiers exist by complexity. Output should be a field-mapping understanding and a clear go/no-go on read-only vs write-back. Always remind buyers: NexCort iQ enhances CAD — it does not replace it. | E18: Agency IT, CAD admins, ECC leadership | F18: Make discovery a required gate before any integration quote. Use it to protect the deal from over-promising. | G18: Not the integration itself; not permission to enable write-back | H18: CAD Integration
A19: CAD Integration | B19: CAD Read-Only Integration | C19: One-way CAD context into NexCort — zero risk to the system of record. | D19: Pulls CAD incident/unit context into the NexCort workspace so dispatchers see structured CAD data while they work. No write path into CAD. This is the default first integration for every PSAP. Complexity tiers (Simple → Advanced) drive one-time fees. Annual maintenance is typically 15–20% of the integration fee, billed separately. | E19: Agency IT + ECC ops who want intelligence without CAD risk | F19: Position as the safe first step. Prove Context Cards / unit awareness before discussing write-back. | G19: Not write-back; not multi-CAD mesh; not AVL overlays by itself | H19: CAD Integration
A20: CAD Integration | B20: CAD Assisted / Automated Write-Back | C20: Human-reviewed (or tightly gated automated) posting into CAD — never in pilot base. | D20: Assisted write-back lets a dispatcher/supervisor submit proposed CAD updates that require human approve/reject with attestation. Automated write-back is rare, agency-explicit, and still fail-closed at every layer. Requires signed CAD write-back addendum and completed discovery. Complexity tiers set one-time fees. RULE FOR EVERY REP: do not include full CAD write-back in pilot base pricing — scope separately after discovery. | E20: Mature PSAPs with IT sponsorship and vendor cooperation | F20: Sell only after read-only success. Emphasize human review and fail-closed design to CAD vendors and CJIS stakeholders. | G20: Not silent automation by default; not included in pilots; not a substitute for CAD training | H20: CAD Integration
A21: CAD Integration | B21: Multi-CAD Connector / CAD-to-CAD Mesh | C21: Regional multi-CAD awareness for mutual aid — high trust, never free. | D21: Connects multiple CAD systems under one tenant and/or enables controlled CAD-to-CAD mesh awareness across mutual-aid partners. This is a Command+-class commercial SKU and a high-complexity delivery. Never offer complimentary. Expect dual-admin consent patterns similar to Agency Share, careful scoping, and longer timelines. Additional CAD vendor connectors are separate one-time fees. | E21: Regional centers, mutual-aid heavy counties, multi-CAD enterprises | F21: Sell into regional readiness and mutual-aid conversations — not single-agency pilots. | G21: Not free; not a weekend install; not automatic write-back across agencies | H21: Feature Add-Ons / CAD Integration
A22: CAD Integration | B22: Map Unit Overlays (AVL) | C22: See units on the map with status and ETA from the CAD/AVL feed. | D22: Shows real-time apparatus markers on operational maps using the agency’s CAD/AVL feed — unit status, distance, ETA. Command+ monthly add-on. Soft-fails cleanly when the feed is unavailable so the rest of the console still works. Strong visual sell in demos; confirm AVL feed access in discovery. | E22: Dispatchers and supervisors who already have AVL in CAD | F22: Demo during a live or replayed call with unit motion. Confirm feed availability before quoting. | G22: Not a standalone AVL system; not GPS tracking invented by NexCort | H22: Feature Add-Ons / CAD Integration
A23: CAD Integration | B23: NG911 Assist | C23: Helps i3-aware PSAPs with diversion, EIDO/additional data, and NG911 metrics — not a phone system replace. | D23: Assist pack for agencies mid-NG911 / i3 upgrade: diversion support, EIDO/additional data assist, and NG911 metrics. There is no single list SKU in the billing catalog yet — quote after ESInet/i3 discovery using the internal range on Feature Add-Ons. Position as meeting them where their NG911 program is. Do not promise telephony rip-and-replace or ESInet replacement. | E23: PSAP directors and IT leads in active NG911 programs | F23: Ask about ESInet vendor and i3 readiness first. Scope a discovery-led quote — don’t invent a fixed SKU on the call. | G23: Not a CPE/telephony replacement; not automatic NG911 certification | H23: Feature Add-Ons
A24: VISION & CAMERAS
A25: Vision & Cameras | B25: NexIQ Vision™ — Standard / Professional / Enterprise | C25: Agency cameras on the live incident — with AI scene assist for authorized roles. | D25: NexIQ Vision™ (formerly NexCort iQ Connect) links existing ONVIF/RTSP facility cameras into the incident console so responders and dispatch/security see the scene without leaving the workflow. Tiers: Standard (up to 10 cameras), Professional (up to 50), Enterprise (unlimited / multi-site KVS). Includes pathing for AI scene observations and vision transcripts for authorized roles — always human-in-the-loop, never autonomous enforcement or facial-recognition promises unless product docs explicitly support them. Never free. | E25: PSAP supervisors, campus/venue/transit security leaders with camera estates | F25: Ask how many cameras and which zones matter on day one. Start Standard; expand by camera count. | G25: Not a VMS replacement; not autonomous policing; not free ‘camera access’ | H25: Feature Add-Ons
A26: Vision & Cameras | B26: Citizen Camera Share (Ring / Nest / Wyze) | C26: Caller or resident grants a time-limited live camera view into the incident. | D26: Consent-based, time-limited share from citizen cameras (Ring live; Nest/Wyze share paths) into the incident workspace. Strong for residential 911 and campus residential life. Privacy language matters: temporary share with consent — not permanent surveillance takeover. Pair with NexIQ Vision™ agency cameras for a complete ‘see the scene’ story. | E26: Residential-heavy PSAPs, campus safety, community policing programs | F26: Lead with consent and time limits. Demo the one-tap share from SMS where available. | G26: Not permanent camera takeover; not a Ring reseller contract by itself | H26: Feature Add-Ons
A27: Vision & Cameras | B27: Camera Integration Setup (one-time) | C27: Paid setup to bridge cameras correctly the first time. | D27: One-time professional services to configure RTSP/ONVIF bridges, zones, and provider connections per camera provider. Quote per provider when the estate is complex. Prevents ‘cameras don’t show up on go-live’ failures that kill executive confidence. | E27: Agency IT / physical security teams | F27: Always attach setup when selling Vision Professional/Enterprise or multi-provider estates. | G27: Not the monthly Vision subscription | H27: Feature Add-Ons
A28: INTELLIGENCE & ANALYTICS
A29: Intelligence & Analytics | B29: iQ Reporting | C29: Daily agency analytics for leaders — never on the dispatcher console. | D29: iQ Reporting is the supervisor/agency-admin analytics surface across verticals (911, campus, venue, transit, hospital). It answers ‘what happened yesterday/this week’ with daily aggregated metrics — not a live dispatcher tool. RBAC blocks dispatcher and front-line roles. On Professional/Command it is included; on Essential sell it as an add-on aligned to the Command Intelligence list band until a dedicated SKU ships. Use it to win supervisors and agency admins who need accountability reporting for leadership and grants. | E29: Supervisors, agency admins, campus/venue/transit admins — never front-line dispatchers | F29: Show a supervisor-only dashboard. Stress that dispatchers are not distracted by reporting UI. | G29: Not a dispatcher widget; not real-time CAD BI; not public open-data publishing | H29: Feature Add-Ons
A30: Intelligence & Analytics | B30: Command Intelligence | C30: Comms-ops intelligence for supervisors — different from the Incident Command Dashboard. | D30: Command Intelligence is a Professional+ communications operations module: call volume, Call Assist containment, translation breakdown, repeat locations, and drill-downs for supervisors and command staff. It is not the same product as Incident Command Dashboard / war rooms. Sell to leaders who want operational intelligence about how the communications center is performing — especially where Call Assist or translation is in play. | E30: Supervisors, communications managers, command staff | F30: Clarify naming early: ‘Command Intelligence’ ≠ ‘Incident Command.’ Bring containment and repeat-location stories. | G30: Not war rooms / major incident boards; not iQ Reporting’s daily vertical pack (related but distinct) | H30: Feature Add-Ons
A31: Intelligence & Analytics | B31: Incident Context Cards | C31: Prior-call and officer-safety context on the live call — included in every plan. | D31: Read-only cards during live 911/ops calls showing prior calls at the location, officer-safety flags, and labeled CAD/Vault sources. Included in all plans at $0 list — use it as a universal value proof in every demo. Explicitly does not include JMS or criminal-history data. When Vault is purchased, Context Cards get richer historical location intelligence. | E31: Every dispatcher and supervisor on any plan | F31: Open demos with a Context Card on a repeat address. Upsell Vault when they ask for ‘all-time’ history. | G31: Not NCIC/JMS; not criminal history; not a paid upsell by itself | H31: Feature Add-Ons
A32: Intelligence & Analytics | B32: NexiQ Vault | C32: Historical CAD/call archive that makes Context Cards smarter after migrations. | D32: Read-only archive of prior CAD/call-record exports for agencies migrating systems or needing deeper location history. Search by address and enrich Context Cards with all-time intelligence. Command+ monthly add-on. No JMS or criminal-history data. Sell when the agency is mid-CAD migration or complains that ‘we lose history every time we change CAD.’ | E32: Agency admins, supervisors, analysts on Command+ journeys | F32: Attach to CAD migration deals and Context Card demos. Emphasize read-only and no criminal databases. | G32: Not a RMS/JMS; not criminal history; not free | H32: Feature Add-Ons
A33: CONTINUITY & COMMAND
A34: Continuity & Command | B34: Response Continuity System (RCS) | C34: Keeps life-safety calls from falling through silent gaps — monitor, geofence arrival, closure gate. | D34: RCS is a Professional+ life-safety persistence module: silent monitor queue, unit geofence arrival confirmation, audio sentinel, escalation paths, and a closure gate with supervisor-override audit. Sell to agencies worried about calls that go quiet, units that never confirm arrival, or closures without accountability. This is an operations-confidence sale, not a shiny AI demo. | E34: PSAP supervisors and quality/ops leaders with life-safety accountability pressure | F34: Tell the story of a quiet line / unconfirmed arrival. Walk the closure-gate audit path with supervisors. | G34: Not silent illegal wiretaps; not a replacement for unit status in CAD | H34: Feature Add-Ons
A35: Continuity & Command | B35: Mutual Aid & MCI Command | C35: When the incident spans agencies, command still has one coordinated playbook. | D35: Command tooling for mutual-aid activation and multi-casualty coordination across PSAP and hospital participants. Complements war rooms and hospital capacity/routing. Sell into regional readiness and grant-funded MCI modernization. Confirm which agencies and roles are in scope before promising a joint go-live. | E35: Regional EMA, large PSAPs, hospital EMS coordinators | F35: Pair with Hospital Routing / MCI modules and Incident Command suite. Great grant narrative. | G35: Not automatic mutual-aid legal authority; not a radio system | H35: Feature Add-Ons / Incident Command
A36: Continuity & Command | B36: Major Incident Management / Command Dashboard / War Rooms | C36: Structured major-incident coordination instead of scattered phone trees and whiteboards. | D36: These Incident Command add-ons (included in Command plan) give supervisors and command staff status boards, collaborative war rooms, and a decision-support command view while local CAD remains system of record. Sell for storms, active incidents, large events, and EOC activity. On Essential/Professional, package as add-ons; on Command, remind them it’s already in the base so you can sell adjacent modules (PIO view, stakeholder pages, Mutual Aid). | E36: Supervisors, agency admins, EOC liaisons | F36: Replay their last big event. Show war room vs. group text chaos. | G36: Not a replacement CAD; not public mass notification by itself | H36: Incident Command
A37: Continuity & Command | B37: Runbooks / Playbooks | C37: Approved steps under stress — so every shift runs the same play. | D37: Operational runbooks/playbooks attached to incident types so staff follow approved steps during high stress. Content must be agency-owned and kept current — sell the discipline, not just the UI. Included or add-on depending on plan (see Incident Command / plan sheets). | E37: Training officers, supervisors, agency admins | F37: Ask who owns SOPs today. Offer to load their top 5 incident types in onboarding. | G37: Not legal advice; not automatic SOP compliance certification | H37: Incident Command
A38: Continuity & Command | B38: Escalation Bridge (live ops) vs Reliability Escalation Engine | C38: Know which escalation you’re selling — live incident path vs IT/ops reliability path. | D38: Live ops Escalation Bridge routes active incident escalation into supervisor/command workflows. The Reliability Escalation Engine (Reliability Ops sheet) is for platform/IT alert promotion and on-call routing when systems degrade. Do not conflate them on a quote. Both matter; different buyers (ops floor vs agency IT/NOC). | E38: Ops supervisors (live) vs Agency IT / NOC (reliability) | F38: Ask whether the pain is ‘calls escalating’ or ‘systems paging.’ Quote the matching sheet. | G38: Not interchangeable products; not a radio console | H38: Feature Add-Ons / Reliability Ops
A39: AI & CALL INTELLIGENCE
A40: AI & Call Intelligence | B40: AI Triage Workflows | C40: Structured AI prompts during intake — dispatcher stays in control. | D40: Tiered AI triage (Basic → Premium by rule depth) that surfaces protocol-oriented suggestions while the call is live. Always position as decision support, never as replacing dispatcher judgment. Pairs with live transcription; without transcription most AI value collapses. Never offer core AI triage as complimentary on a paid order. | E40: Dispatchers and supervisors; ECC directors buying consistency | F40: Demo mid-call suggestions. Repeat: human remains accountable. | G40: Not autonomous dispatch; not a protocol certification body | H40: AI Intelligence
...

Sheet Essential
A1: NEXCORT IQ — INTERNAL PRICING GUIDE
A2: NEXCORT IQ ESSENTIAL
A3: Small municipalities · Single-site PSAPs · Pilot deployments · Up to 10 dispatcher seats
A5: BASE SUBSCRIPTION FEES
A6: Item | B6: Tier 1 Micro | C6: Tier 2 Small | D6: Tier 3 Medium | E6: Tier 4 Large | F6: Range (docx) | G6: Notes
A7: Seats | B7: 1–3 | C7: 4–6 | D7: 7–8 | E7: 9–10 | F7: 1–10
A8: Call Volume / Month | B8: <2,000 | C8: 2K–3.5K | D8: 3.5K–4.5K | E8: 4.5K–5K | F8: Varies
A9: Monthly Fee | B9: 2800 | C9: 4200 | D9: 5400 | E9: 6000 | F9: $3,500–$7,500 | G9: Inputs in blue
A10: Annual Fee | B10: =IFERROR(B8*12,"—") | C10: =IFERROR(C8*12,"—") | D10: =IFERROR(D8*12,"—") | E10: =IFERROR(E8*12,"—") | F10: $42K–$90K | G10: Auto-calculated
A11: Recommended Pilot (90-day) | B11: 25000 | C11: 30000 | D11: 37500 | E11: 50000 | F11: $25K–$50K
A12: Setup / Implementation | B12: 10000 | C12: 15000 | D12: 20000 | E12: 25000 | F12: $10K–$25K | G12: One-time
A14: SEAT OVERAGE PRICING
A15: Seat Type | B15: Included in Base | C15: Overage Rate / Month | D15: Notes
A16: Dispatcher Seats | B16: Up to 10 | C16: $150 / seat / month | D16: Seats 11+
A17: Admin / Supervisor Seats | B17: Up to 3 | C17: $100 / seat / month | D17: Seats 4+
A19: INCLUDED CAPABILITIES
A20: Capability | B20: Included? | C20: Notes
A21: Web Application Access | B21: Yes
A22: Desktop Application Access | B22: Yes | C22: Windows & Mac
A23: Role-Based Access Control (RBAC) | B23: Yes
A24: Agency Admin Console | B24: Yes
A25: Core Reporting | B25: Yes
A26: Audit Logs | B26: Yes | C26: CJIS-aware retention
A27: AI-Assisted Intake | B27: Yes
A28: Live Transcription | B28: Yes
A29: Call Triage Workflows | B29: Yes
A30: Call / Session History | B30: Yes
A31: Active Incident View | B31: Yes
A32: Dispatcher Console | B32: Limited | C32: Full in Professional+
A33: Multilingual Intake | B33: Limited | C33: Upgrade for full translation
A34: Language Auto-Detection | B34: Limited
A35: QA Review Tools | B35: Limited | C35: Upgrade for full QA suite
A36: Incident Timeline Reconstruction | B36: Limited
A37: Standard Onboarding | B37: Yes
A38: Integration Assistance | B38: Limited
A40: ESSENTIAL ADD-ON CANDIDATES
A41: Add-On | B41: Price Low / Month | C41: Price High / Month | D41: Notes
A42: Live Translation | B42: 1000 | C42: 3000
A43: Text-to-Voice Support | B43: 750 | C43: 2500
A44: Caller Photo Upload | B44: 500 | C44: 1500
...

Sheet Professional
A1: NEXCORT IQ — INTERNAL PRICING GUIDE
A2: NEXCORT IQ PROFESSIONAL
A3: Growing counties & cities · Full features · Translation · QA · Analytics · Up to 25 dispatcher seats
A5: BASE SUBSCRIPTION FEES
A6: Item | B6: Small Pro T1 | C6: Medium Pro T2 | D6: Large Pro T3 | E6: Max Pro T4 | F6: Range (docx) | G6: Notes
A7: Seats | B7: 1–10 | C7: 11–18 | D7: 19–23 | E7: 24–25 | F7: 1–25
A8: Call Volume / Month | B8: <10,000 | C8: 10K–18K | D8: 18K–23K | E8: 23K–25K | F8: Varies
A9: Monthly Fee | B9: 8500 | C9: 13000 | D9: 15500 | E9: 18000 | F9: $8,500–$18,000
A10: Annual Fee | B10: =IFERROR(B8*12,"—") | C10: =IFERROR(C8*12,"—") | D10: =IFERROR(D8*12,"—") | E10: =IFERROR(E8*12,"—") | F10: $102K–$216K | G10: Auto-calculated
A11: Recommended Pilot (90-day) | B11: 50000 | C11: 70000 | D11: 87500 | E11: 100000 | F11: $50K–$100K
A12: Setup / Implementation | B12: 25000 | C12: 40000 | D12: 50000 | E12: 60000 | F12: $25K–$60K | G12: One-time
A14: SEAT OVERAGE PRICING
A15: Seat Type | B15: Included in Base | C15: Overage Rate / Month | D15: Notes
A16: Dispatcher Seats | B16: Up to 25 | C16: $125 / seat / month | D16: Seats 26+
A17: Admin / Supervisor Seats | B17: Up to 8 | C17: $100 / seat / month | D17: Seats 9+
A19: INCLUDED CAPABILITIES (ALL ESSENTIAL + THESE)
A20: Capability | B20: Included? | C20: Notes
A21: Full Dispatcher Monitoring Console | B21: Yes
A22: Channel / Talk Group Monitoring | B22: Yes
A23: Non-Emergency Intake Queue | B23: Yes
A24: Backlog and SLA Tracking | B24: Yes
A25: Live Translation | B25: Yes | C25: Included — not add-on
A26: Text-to-Voice Support | B26: Yes
A27: Language Auto-Detection | B27: Yes
A28: Caller Photo Upload | B28: Yes
A29: Caller Video Upload | B29: Yes
A30: Media Audit Trail | B30: Yes
A31: Supervisor QA Tools | B31: Yes
A32: Scorecards | B32: Yes
A33: Coaching Notes | B33: Yes
A34: Team Performance Dashboards | B34: Yes
A35: Call Quality Trends | B35: Yes
A36: Incident Timeline Reconstruction | B36: Yes
A37: Post-Incident Reviews | B37: Yes
A38: Integration Assistance | B38: Yes
A39: Priority Support | B39: Yes | C39: Included
A41: LIMITED / ADD-ON IN PROFESSIONAL
A42: Capability | B42: Status | C42: Price Low / Month | D42: Price High / Month | E42: Notes
A43: Live Caller Media Streaming | B43: Limited | C43: 2500 | D43: 6000 | E43: WebRTC real-time
A44: Runbooks / Playbooks | B44: Limited | C44: 1500 | D44: 4000
...

Sheet Command
A1: NEXCORT IQ — INTERNAL PRICING GUIDE
A2: NEXCORT IQ COMMAND
A3: Large agencies · Regional command environments · Major incident coordination · Up to 75 dispatcher seats
A5: BASE SUBSCRIPTION FEES
A6: Item | B6: Small Cmd T1 | C6: Medium Cmd T2 | D6: Large Cmd T3 | E6: Max Cmd T4 | F6: Range (docx) | G6: Notes
A7: Seats | B7: 1–25 | C7: 26–50 | D7: 51–65 | E7: 66–75 | F7: 1–75
A8: Call Volume / Month | B8: <30,000 | C8: 30K–60K | D8: 60K–85K | E8: 85K–100K | F8: Varies
A9: Monthly Fee | B9: 22500 | C9: 31000 | D9: 40000 | E9: 50000 | F9: $22,500–$50,000
A10: Annual Fee | B10: =IFERROR(B8*12,"—") | C10: =IFERROR(C8*12,"—") | D10: =IFERROR(D8*12,"—") | E10: =IFERROR(E8*12,"—") | F10: $270K–$600K | G10: Auto-calculated
A11: Recommended Pilot (90–180 days) | B11: 100000 | C11: 150000 | D11: 200000 | E11: 250000 | F11: $100K–$250K | G11: 6-month standard
A12: Setup / Implementation | B12: 75000 | C12: 100000 | D12: 125000 | E12: 150000 | F12: $75K–$150K | G12: One-time
A14: SEAT OVERAGE PRICING
A15: Seat Type | B15: Included | C15: Overage Rate / Month | D15: Notes
A16: Dispatcher Seats | B16: Up to 75 | C16: $100 / seat / month | D16: Seats 76+
A17: Admin / Supervisor / Command Seats | B17: Up to 20 | C17: $85 / seat / month | D17: Seats 21+
A19: INCLUDED CAPABILITIES (ALL PROFESSIONAL + THESE)
A20: Capability | B20: Included? | C20: Notes
A21: Major Incident Management | B21: Yes
A22: Command Dashboard | B22: Yes
A23: War Rooms | B23: Yes
A24: Runbooks / Playbooks | B24: Yes
A25: Post-Incident Review Tools | B25: Yes
A26: Stakeholder Status Pages | B26: Yes
A27: Monitoring Integrations | B27: Yes
A28: Alert Correlation | B28: Yes
A29: Escalation Engine | B29: Yes
A30: On-Call Routing | B30: Yes
A31: SLO Dashboards | B31: Yes
A32: Reliability Reporting | B32: Yes
... A34: Dedicated Rollout Planning | B34: Yes
A36: LIMITED / ADD-ON IN COMMAND
A37: Capability | B37: Status | C37: Price Low | D37: Price High | E37: Type | F37: Notes
A38: Multi-Site Deployment Support | B38: Limited | C38: 25000 | D38: 100000 | E38: One-time
A39: Custom Security / Compliance Review | B39: Limited | C39: 15000 | D39: 75000 | E39: One-time
A40: Custom CAD Connector | B40: Add-on | C40: 50000 | D40: 250000 | E40: One-time
A41: Dedicated Support Engineer | B41: Add-on | C41: 8000 | D41: 20000 | E41: / month
A42: Onsite Quarterly Review | B42: Add-on | C42: 7500 | D42: 20000 | E42: Per visit
A43: Advanced Data Retention Architecture | B43: Add-on | C43: 10000 | D43: 75000 | E43: One-time
A45: SALES POSITIONING — Command Plan
A46: Best for proving value during high-complexity incidents and cross-team response.
...

Sheet Enterprise
A1: NEXCORT IQ — INTERNAL PRICING GUIDE
A2: ENTERPRISE / STATEWIDE
A3: Multi-agency · 50–500+ seats · Statewide programs · Custom architecture · Dedicated infrastructure
A5: BASE SUBSCRIPTION FEES
A6: Deployment Size | B6: Agencies | C6: Seats | D6: Monthly Fee Range | E6: Annual Fee Range | F6: Notes
A7: Small Enterprise | B7: 2–5 | C7: 50–150 | D7: $60K–$100K / month | E7: $720K–$1.2M / year
A8: Medium Enterprise | B8: 6–15 | C8: 150–300 | D8: $100K–$175K / month | E8: $1.2M–$2.1M / year
A9: Large Enterprise | B9: 16–30 | C9: 300–500 | D9: $175K–$250K / month | E9: $2.1M–$3M / year
A10: Statewide | B10: 30+ | C10: 500+ | D10: $250K+ / month | E10: $3M–$10M+ / year | F10: Custom contract
A12: SEAT OVERAGE
A13: Seat Type | B13: Overage Rate | C13: Notes
A14: Dispatcher Seats | B14: $75–$100 / seat / month | C14: Negotiated per contract
A15: Admin / Supervisor Seats | B15: Custom | C15: Per SOW
A17: SETUP & IMPLEMENTATION
A18: Item | B18: Low | C18: High | D18: Notes
A19: Setup / Implementation | B19: 20000 | C19: 75000 | D19: Per SOW — wide range
A20: Multi-Site Deployment Support | B20: 25000 | C20: 100000 | D20: One-time per scope
A21: Custom Security / Compliance Review | B21: 15000 | C21: 75000 | D21: One-time
A22: Advanced Rollout Services | B22: Custom | C22: Custom | D22: SOW required
A24: INCLUDED CAPABILITIES
A25: Capability | B25: Included? | C25: Notes
A26: All Command capabilities (as applicable) | B26: Yes
A27: Multi-Agency Architecture | B27: Yes
A28: Multi-Site Deployment Planning | B28: Yes
A29: Custom Integrations | B29: Yes | C29: Per SOW
A30: Custom Retention / Security Options | B30: Yes
A31: Advanced Rollout Services | B31: Yes
A32: Procurement and Compliance Support | B32: Yes
A33: Tailored Deployment Architecture | B33: Yes
A34: Dedicated Architecture Planning | B34: Yes
A35: Executive Reporting | B35: Yes
A36: Custom SOW | B36: Yes
A38: SALES POSITIONING — Enterprise / Statewide
A39: Best sales angle: NexCort iQ becomes a long-term public safety modernization platform.
A40: Strong fit for grant-funded programs, large procurements, and regional emergency management transformation.
A41: Every Enterprise deal requires a custom SOW — do not quote fixed prices without Sales Director sign-off.
A42: ⚠ INTERNAL USE ONLY — Enterprise pricing requires VP Sales + Sales Director approval before quoting.

Sheet CAD Integration
A1: NEXCORT IQ — INTERNAL PRICING GUIDE
A2: CAD INTEGRATION ADD-ONS
A3: One-time fees · Complexity-tiered · NexCort iQ enhances CAD — it does not replace it
A5: DISCOVERY & PLANNING
A6: Service | B6: Price Low | C6: Price High | D6: Notes
A7: Basic CAD Discovery Workshop | B7: 7500 | C7: 7500 | D7: Single CAD, standard environment
A8: Standard CAD Discovery Workshop | B8: 10000 | C8: 10000 | D8: Recommended starting point
A9: Advanced CAD Discovery Workshop | B9: 15000 | C9: 15000 | D9: Complex multi-CAD environments
A10: CAD Field Mapping Document | B10: 7500 | C10: 20000
A11: CAD Integration Audit Logging Package | B11: 10000 | C11: 35000
A12: CAD Rollback and Failover Planning | B12: 10000 | C12: 30000
A14: CAD VENDOR COORDINATION
A15: Tier | B15: Price | C15: Description
A16: Basic Vendor Coordination | B16: 8000 | C16: Single CAD vendor, standard API
A17: Standard Vendor Coordination | B17: 11000 | C17: Moderate complexity
A18: Premium Vendor Coordination | B18: 16000 | C18: Multi-vendor or legacy CAD
A19: CAD Sandbox Testing Package | B19: 6000 | C19: Included or $15K–$50K depending on scope
A21: READ-ONLY INTEGRATION
A22: Complexity Tier | B22: One-Time Fee | C22: Description
A23: Tier 1 — Simple | B23: 10000 | C23: Standard REST or webhook
A24: Tier 2 — Standard | B24: 18500 | C24: Moderate mapping / transform
A25: Tier 3 — Complex | B25: 23425 | C25: Legacy protocol / custom adapter
A26: Tier 4 — Advanced | B26: 36450 | C26: Multi-system / real-time
A28: ASSISTED WRITE-BACK INTEGRATION
A29: Complexity Tier | B29: One-Time Fee | C29: Description
A30: Tier 1 — Simple | B30: 28500 | C30: Basic write-back with confirmation
A31: Tier 2 — Standard | B31: 34250 | C31: Standard bidirectional
A32: Tier 3 — Complex | B32: 44000 | C32: Complex data mapping
A33: Tier 4 — Advanced | B33: 51600 | C33: Full bidirectional + validation
A35: AUTOMATED WRITE-BACK INTEGRATION
A36: Complexity Tier | B36: One-Time Fee | C36: Description
A37: Tier 1 — Simple | B37: 46000 | C37: Automated rules-based write-back
A38: Tier 2 — Standard | B38: 58000 | C38: Full automation with logging
A39: Tier 3 — Complex | B39: 67000 | C39: Complex event-driven automation
A40: Tier 4 — Advanced | B40: 74000 | C40: Custom AI-assisted write-back
A42: ADDITIONAL CAD CONNECTORS
A43: Item | B43: Low | C43: High | D43: Notes
A44: Additional CAD Vendor Connector | B44: 75000 | C44: 150000 | D44: Per connector — one-time
A46: RULE: Do NOT include full CAD write-back in pilot base pricing. Scope separately after discovery, sandbox testing, and vendor validation.
A47: Annual maintenance on integrations: 15–20% of integration fee, billed separately.

Sheet Caller Media
A1: NEXCORT IQ — INTERNAL PRICING GUIDE
A2: CALLER TEXT, PHOTO & VIDEO ADD-ONS
A3: SMS links · Photo upload · Video upload · Live streaming · Redaction · Evidence retention
A5: SMS & TEXT
A6: Service | B6: Monthly Fee Low | C6: Monthly Fee High | D6: Notes
A7: Caller SMS Link Generation | B7: 1500 | C7: 5000
A8: Text-Only Emergency Conversation Link | B8: 2000 | C8: 7500 | D8: Async text triage
A10: PHOTO UPLOAD
A11: Tier | B11: Monthly Fee Low | C11: Monthly Fee High | D11: Notes
A12: Basic (<500 photos/mo, 5MB, 30-day retention) | B12: 1000 | C12: 3500
A13: Standard (<2K photos/mo, 10MB, 90-day retention) | B13: 1000 | C13: 3500
A14: Premium (5K+ photos/mo, 25MB, 1-year retention) | B14: 2000 | C14: 4000
A16: VIDEO UPLOAD & LIVE STREAMING
A17: Service | B17: Monthly Fee Low | C17: Monthly Fee High | D17: Notes
A18: Caller Video Upload | B18: 2500 | C18: 8500 | D18: Async upload
A19: Live Caller Video Streaming | B19: 5000 | C19: 20000 | D19: WebRTC · real-time
A20: Media Audit Trail | B20: 1500 | C20: 5000 | D20: Chain-of-custody logging
A21: Evidence Retention Controls | B21: 2500 | C21: 10000
A22: Secure Media Storage Package | B22: 1500 | C22: 7500 | D22: Plus storage overages
A23: Media Redaction Workflow | B23: 5000 | C23: 20000 | D23: High-margin — scope carefully
A24: Large-Volume Media Package | B24: Custom | C24: Custom | D24: Custom quote required
A26: SALES POSITIONING — Caller Media Add-Ons
A27: Gives dispatchers more real-time context before responders arrive.
A28: Useful when callers cannot safely speak or when visual context improves situational awareness.
A29: Supports better documentation through audit trails and evidence retention.
A30: ⚠ INTERNAL USE ONLY

Sheet Supervisor QA
A1: NEXCORT IQ — INTERNAL PRICING GUIDE
A2: SUPERVISOR & QA ADD-ONS
A3: Scorecards · Coaching · Dashboards · QA rubrics · Analytics · AI grading
A5: QA & COACHING MODULES
A6: Module | B6: Monthly Fee Low | C6: Monthly Fee High | D6: Notes
A7: QA Review Tools | B7: 1500 | C7: 5000 | D7: Full suite — replaces Limited in Essential
A8: Dispatcher Scorecards | B8: 1000 | C8: 4000 | D8: Per-call scoring templates
A9: Coaching Notes | B9: 1000 | C9: 4000 | D9: Supervisor annotation layer
A10: Team Performance Dashboards | B10: 2000 | C10: 7500 | D10: Real-time supervisor view
A11: Call Quality Trends | B11: 2000 | C11: 7500 | D11: Trend reporting + export
A12: Supervisor Training Dashboard | B12: 2500 | C12: 10000
A13: AI QA Scoring Model | B13: 2500 | C13: 10000 | D13: AI-assisted grading
A14: Monthly QA Analytics Report | B14: 2500 | C14: 7500
A16: CUSTOM QA DEVELOPMENT
A17: Item | B17: Price Low | C17: Price High | D17: Type | E17: Notes
A18: Custom QA Scoring Rubric | B18: 7500 | C18: 25000 | D18: One-time
A20: BUNDLE: Scorecards + Coaching Notes + Team Dashboards — 15% discount when ordered together.
A21: SALES POSITIONING — Supervisor & QA Add-Ons
A22: Helps supervisors identify training gaps and improve consistency.
A23: Useful for agencies focused on compliance, coaching, and continuous improvement.
A24: Custom QA rubric is a high-value one-time add-on — scope after pilot.
A25: ⚠ INTERNAL USE ONLY

Sheet Transcription
A1: NEXCORT IQ — INTERNAL PRICING GUIDE
A2: TRANSCRIPTION & TRANSLATION ADD-ONS
A3: Enhanced accuracy · Speaker diarization · Live translation · Language packs · Text-to-voice
A5: ENHANCED TRANSCRIPTION ACCURACY
A6: Volume Tier | B6: Monthly Fee | C6: Notes
A7: Tier 1 (<5K calls/month) | B7: 1500
A8: Tier 2 (5K–15K calls/month) | B8: 3000
A9: Tier 3 (15K+ calls/month) | B9: 5000
A11: SPEAKER SEPARATION (DIARIZATION)
A12: Volume Tier | B12: Monthly Fee | C12: Notes
A13: Tier 1 (<5K calls/month) | B13: 1000
A14: Tier 2 (5K–15K calls/month) | B14: 2500
A15: Tier 3 (15K+ calls/month) | B15: 4000
A17: LIVE TRANSLATION
A18: Tier | B18: Languages / Volume | C18: Monthly Fee | D18: Notes
A19: Tier 1 | B19: 2–3 languages, <2K translations/mo | C19: 2500
A20: Tier 2 | B20: 4–6 languages, 2K–5K translations/mo | C20: 5500
A21: Tier 3 | B21: 7–10 languages, 5K–10K translations/mo | C21: 8000
A22: Tier 4 | B22: 10+ languages, 10K+ translations/mo | C22: 10000 | D22: Custom SLA available
A24: LANGUAGE PACKS & ADDITIONAL SERVICES
A25: Item | B25: Monthly Fee Low | C25: Monthly Fee High | D25: Notes
A26: Multilingual Intake Package | B26: 1500 | C26: 5000
A27: Text-to-Voice Support | B27: 1500 | C27: 5000
A28: Top 10 Language Support Package | B28: 3500 | C28: 12500 | D28: Bundled
A29: Top 15 Language Support Package | B29: 5000 | C29: 18000 | D29: Bundled
A30: Custom Language Package | B30: 1000 | C30: 4000 | D30: Per language / month
A31: Translation Audit Trail | B31: 1000 | C31: 4000
A33: SALES POSITIONING — Transcription & Translation Add-Ons
A34: Supports diverse communities and improves language access during intake.
A35: Helps dispatchers understand callers faster and create more complete incident records.
A36: Live translation is included in Professional+ — upsell language packs for depth.
A37: ⚠ INTERNAL USE ONLY

Sheet Incident Command
A1: NEXCORT IQ — INTERNAL PRICING GUIDE
A2: INCIDENT COMMAND & COLLABORATION ADD-ONS
A3: War rooms · Command dashboards · Runbooks · Timelines · Stakeholder pages · EOC support
A5: INCIDENT COMMAND ADD-ONS
A6: Module | B6: Monthly Fee Low | C6: Monthly Fee High | D6: Notes
A7: Major Incident Management | B7: 5000 | C7: 20000 | D7: Included in Command plan
A8: Command Dashboard | B8: 5000 | C8: 20000 | D8: Included in Command plan
A9: War Rooms | B9: 3500 | C9: 15000 | D9: Included in Command plan
A10: Runbooks / Playbooks | B10: 2500 | C10: 12500 | D10: Included in Command plan
A11: Incident Timeline Reconstruction | B11: 2500 | C11: 10000
A12: Post-Incident Reviews | B12: 2500 | C12: 10000
A13: Stakeholder Status Pages | B13: 3500 | C13: 15000
A14: Public Information Officer View | B14: 2500 | C14: 10000
A15: Executive Incident Briefing Module | B15: 3500 | C15: 15000
A17: SALES POSITIONING — Incident Command Add-Ons
A18: Moves agencies from scattered communication to structured incident coordination.
A19: Valuable during storms, active incidents, large events, mutual aid, and EOC activity.
A20: Note: Major incident management and command dashboard are included in Command plan — upsell for Professional agencies.
A21: ⚠ INTERNAL USE ONLY

Sheet Reliability Ops
A1: NEXCORT IQ — INTERNAL PRICING GUIDE
A2: RELIABILITY & TECHNICAL OPERATIONS ADD-ONS
A3: Monitoring · Alert correlation · Escalation · On-call routing · SLOs · CloudWatch
A5: RELIABILITY & MONITORING ADD-ONS
A6: Module | B6: Monthly Fee Low | C6: Monthly Fee High | D6: Notes
A7: Monitoring Integrations | B7: 2500 | C7: 10000 | D7: Included in Command plan
A8: Alert Correlation | B8: 2500 | C8: 10000
A9: Escalation Engine | B9: 2500 | C9: 10000
A10: On-Call Routing | B10: 2500 | C10: 10000
A11: SLO Dashboards | B11: 2000 | C11: 7500
A12: Reliability Reporting | B12: 2000 | C12: 7500
A13: 24/7 Incident Support Upgrade | B13: 7500 | C13: 25000
A15: ONE-TIME RELIABILITY SERVICES
A16: Item | B16: Price Low | C16: Price High | D16: Type | E16: Notes
A17: CloudWatch Dashboard Package | B17: 5000 | C17: 20000 | D17: One-time
A18: Agency-Specific Monitoring Connector | B18: 10000 | C18: 50000 | D18: One-time
A20: SALES POSITIONING — Reliability & Tech Ops Add-Ons
A21: Gives agencies confidence in system uptime and accountability.
A22: Supports technical transparency during mission-critical operations.
A23: Position for agencies with existing NOC/SOC or formal on-call processes.
A24: ⚠ INTERNAL USE ONLY

Sheet Onsite Services
A1: NEXCORT IQ — INTERNAL PRICING GUIDE
A2: ONSITE DEPLOYMENT SERVICES
A3: Discovery · Installation · Go-live support · Floor support · Travel policy
A5: ONSITE SERVICE RATES
A6: Service | B6: Price Low | C6: Price High | D6: Plus Travel? | E6: Notes
A7: Onsite Discovery Visit | B7: 7500 | C7: 15000 | D7: Yes
A8: Onsite Installation Support | B8: 15000 | C8: 35000 | D8: Yes
A9: Onsite Pilot Launch Support | B9: 20000 | C9: 50000 | D9: Yes
A10: Onsite Production Go-Live Support | B10: 35000 | C10: 100000 | D10: Yes | E10: High-value, plan carefully
A11: Onsite CAD / Vendor Integration Workshop | B11: 15000 | C11: 50000 | D11: Yes
A12: Onsite Dispatcher Floor Support | B12: 10000 | C12: 25000 | D12: Yes | E12: Per week
A13: Onsite Executive Briefing | B13: 7500 | C13: 20000 | D13: Yes
A14: Onsite After-Action Review | B14: 10000 | C14: 30000 | D14: Yes
A16: TRAVEL POLICY
A17: Travel Item | B17: Policy | C17: Notes
A18: Airfare | B18: Actual cost | C18: Economy unless >3 hrs
A19: Hotel | B19: Actual cost
A20: Rental Car / Rideshare | B20: Actual cost
A21: Meals / Per Diem | B21: Federal GSA rate or actual | C21: Whichever is lower
A22: Travel Admin Fee | B22: Optional 10% markup | C22: Must be agreed in SOW
A23: Minimum Onsite Billing | B23: 2 days | C23: Applies to all onsite work
A25: SALES POSITIONING — Onsite Services
A26: Reduces rollout risk by putting NexCort iQ experts with agency staff.
A27: Especially valuable for complex workflows, multiple stakeholders, or limited internal IT.
A28: Always scope travel separately — never bundle into a fixed project price without a travel cap clause.
A29: ⚠ INTERNAL USE ONLY

Sheet Training
A1: NEXCORT IQ — INTERNAL PRICING GUIDE
A2: TRAINING PRICING
A3: Remote & onsite · Dispatcher · Supervisor · Admin · Train-the-trainer · Custom
A5: REMOTE TRAINING
A6: Package | B6: Price Low | C6: Price High | D6: Notes
A7: Standard Onboarding | B7: Included | C7: Included | D7: Included in all plans
A8: Remote Admin Training | B8: 2500 | C8: 7500 | D8: Per session
A9: Remote Dispatcher Training | B9: 2500 | C9: 10000 | D9: Per session
A10: Remote Supervisor Training | B10: 3500 | C10: 12500 | D10: Per session
A12: ONSITE TRAINING (plus travel)
A13: Package | B13: Price Low | C13: Price High | D13: Plus Travel? | E13: Notes
A14: Onsite Dispatcher Training | B14: 10000 | C14: 30000 | D14: Yes
A15: Onsite Supervisor Training | B15: 10000 | C15: 30000 | D15: Yes
A17: ADVANCED TRAINING PACKAGES
A18: Package | B18: Price Low | C18: Price High | D18: Notes
A19: Train-the-Trainer Package | B19: 15000 | C19: 50000
A20: Custom Training Materials | B20: 5000 | C20: 20000 | D20: One-time development fee
A21: Annual Refresher Training | B21: 10000 | C21: 50000 | D21: Per year
A23: SALES POSITIONING — Training Pricing
A24: Training protects the agency from workflow confusion and reduces support burden.
A25: Helps teams understand what NexCort iQ does vs. CAD, CPE, SOPs, and AI decision support.
A26: Train-the-Trainer is high-margin and creates internal champions — recommend for Command+.
A27: ⚠ INTERNAL USE ONLY
A29: VENUE / CONVENTION SECURITY TRAINING (aligned RFP 2396IP)
A30: Package | B30: Price Low | C30: Price High | D30: Notes
A31: Venue Security end-user training (virtual) | B31: 1500 | C31: 1500 | D31: Per session · up to 20 · 2 hrs · RFP 2396IP optional rate
A32: Venue Security administrator training (virtual) | B32: 2000 | C32: 2000 | D32: Per session · up to 5 admins · 3 hrs · RFP 2396IP optional rate
A33: Venue Security training package (4 sessions) | B33: 3000 | C33: 3000 | D33: 2 end-user + 2 admin · included in Security Dept impl package

Sheet Support
A1: NEXCORT IQ — INTERNAL PRICING GUIDE
A2: SUPPORT PACKAGES
A3: Standard · Priority · Mission-Critical · Dedicated
A5: SUPPORT TIERS OVERVIEW
A6: Support Tier | B6: User Range | C6: Monthly Fee | D6: Response SLA | E6: Key Features | F6: Notes
A7: Standard Support | B7: All plans | C7: Included | D7: Business hours | E7: Email + KB + onboarding | F7: Included in base
A8: Priority Support — Small | B8: <25 users | C8: $2,500/mo | D8: 4-hour response | E8: Named contact + monthly review
A9: Priority Support — Medium | B9: 25–75 users | C9: $5,000/mo | D9: 4-hour response | E9: Named contact + monthly review
A10: Priority Support — Large | B10: 75+ users | C10: $7,500/mo | D10: 2-hour response | E10: Named contact + monthly review
A11: Mission-Critical Support | B11: Command+ | C11: Custom | D11: 1-hour response | E11: 24/7 · escalation handling · exec reviews | F11: Recommended for Command+
A13: DEDICATED SUPPORT RESOURCES
A14: Resource | B14: Monthly Fee Low | C14: Monthly Fee High | D14: Notes
A15: Dedicated Support Engineer | B15: 8000 | C15: 20000 | D15: Named engineer, SLA-bound
A16: Customer Success Manager (CSM) | B16: Custom | C16: Custom | D16: Enterprise / statewide accounts
A17: Dedicated Solution Architect | B17: Custom | C17: Custom | D17: Complex integration programs
A18: Dedicated 24/7 Support Team | B18: Custom | C18: Custom | D18: Per contract
A20: SALES POSITIONING — Support Packages
A21: Mission-Critical support recommended for Command, Enterprise, and any agency in active production.
A22: Dedicated support turns NexCort iQ from a software vendor into an operational partner.
A23: Priority support is included in Professional — be clear that Mission-Critical is an upgrade.
A24: ⚠ INTERNAL USE ONLY
A26: VENUE / CONVENTION — EXTENDED BUSINESS HOURS (RFP 2396IP)
A27: Support Tier | B27: User Range | C27: Fee | D27: Response SLA | E27: Key Features | F27: Notes
A28: Extended Business Hours Support | B28: Venue Security Dept (<25 users) | C28: $7,200/yr ($600/mo) | D28: P1: 1-hour · P2: 4-hour | E28: 8 AM–8 PM ET Mon–Fri · weekend email ack 4-hr · patches | F28: List rate used on RFP 2396IP — between Standard (included) and Priority ($2,500/mo)

Sheet Storage Overages
A1: NEXCORT IQ — INTERNAL PRICING GUIDE
A2: STORAGE, USAGE & OVERAGES
A3: Included limits by plan · Per-unit overage rates · Call volume · Transcription · Media
A5: INCLUDED USAGE BY PLAN
A6: Resource | B6: Essential | C6: Professional | D6: Command | E6: Enterprise | F6: Notes
A7: Storage | B7: 100 GB | C7: 500 GB | D7: 2 TB | E7: Custom | F7: Expandable via add-on
A8: Call Recording Retention | B8: 90 days | C8: 180 days | D8: 1 year | E8: Custom
A9: Transcription Volume | B9: Included | C9: Included | D9: Included | E9: Custom | F9: Volume limits per contract
A10: Translation Requests | B10: Limited | C10: Included | D10: Included | E10: Custom
A11: API Calls / Month | B11: Standard | C11: Standard | D11: High | E11: Custom
A12: Media Storage (photos/video) | B12: Limited | C12: Standard | D12: Enhanced | E12: Custom
A14: OVERAGE RATES
A15: Resource | B15: Overage Rate | C15: Unit | D15: Notes
A16: Additional Storage | B16: 0.08 | C16: per GB / month | D16: S3 standard + margin
A17: Additional Call Volume | B17: 0.003 | C17: per call over limit | D17: Blended AI processing cost
A18: Additional Transcription | B18: 0.01 | C18: per minute over limit
A19: Additional Translation Requests | B19: 0.05 | C19: per request over limit
A20: Additional Photo Storage | B20: 0.05 | C20: per 100 photos over limit
A21: Archive Storage | B21: 0.02 | C21: per GB / month | D21: Cold storage tier
A22: Data Export | B22: 0.1 | C22: per GB exported | D22: Large exports only
A23: High-Volume API Use | B23: Custom | C23: Custom | D23: Negotiate in contract
A25: SALES POSITIONING — Storage & Overages
A26: Overages protect both the agency and NexCort iQ by allowing flexible usage without forcing an immediate plan change.
A27: Useful during storms, major incidents, seasonal spikes, or large-scale emergencies.
A28: Always discuss expected call volumes during discovery to right-size the plan before signing.
A29: ⚠ INTERNAL USE ONLY
A31: VENUE SECURITY DEPARTMENT STORAGE (RFP 2396IP)
A32: Item | B32: Rate | C32: Unit | D32: Notes
A33: Included storage package (500 GB + 7-year retention) | B33: $3,600 | C33: per year | D33: Quoted as recurring line on Security Dept deals
A34: Additional storage (Venue Security model) | B34: $300 | C34: per 100 GB / year | D34: Min 100 GB · differs from PSAP $0.08/GB/mo overage

Sheet Pilot Programs
A1: NEXCORT IQ — INTERNAL PRICING GUIDE
A2: PILOT PROGRAMS
A3: Pre-packaged pilot bundles for common agency profiles
A5: PILOT PROGRAM OVERVIEW
A6: Program | B6: Duration | C6: Fee Low | D6: Fee High | E6: Typical Scope | F6: Notes
A7: Small City Pilot | B7: 90 days | C7: 20000 | D7: 40000 | E7: Essential + setup + onboarding + training + CAD discovery | F7: Grant-friendly
A8: County Professional Pilot | B8: 90 days | C8: 50000 | D8: 100000 | E8: Professional + translation + caller media + CAD discovery/read-only + training
A9: Command Center Pilot | B9: 90–180 days | C9: 100000 | D9: 250000 | E9: Command + CAD read-only + major incident + war rooms + onsite + training
A10: Enterprise / Statewide Pilot | B10: 6 months | C10: 250000 | D10: 750000 | E10: Enterprise architecture + multi-site + custom integrations + dedicated support | F10: Custom SOW required
A12: SALES POSITIONING — Small City Pilot
A13: Smaller municipalities that want to evaluate NexCort iQ without a full production commitment.
A14: Usually includes Essential-level access, setup, onboarding, training, and CAD discovery.
A15: Sales angle: low-risk, practical way to test value, collect feedback, and support grant-funded modernization.
A17: SALES POSITIONING — County Professional Pilot
A18: Mid-size cities, counties, or regional PSAPs ready for a broader operational test.
A19: Includes Professional-level features: translation, caller media, QA, and supervisor visibility.
A20: Sales angle: demonstrates value across multiple workflows — not just basic AI triage.
A22: SALES POSITIONING — Command Center Pilot
A23: Larger agencies, EOCs, or regional response environments.
A24: May include Command-level tools, war rooms, onsite support, and expanded training.
A25: Sales angle: proves NexCort iQ as a command and coordination platform.
... A32: ⚠ INTERNAL USE ONLY — Pilot pricing to be approved by Sales Director before quoting.

Sheet Discounting
A1: NEXCORT IQ — INTERNAL PRICING GUIDE
A2: DISCOUNTING RULES
A3: Internal — protect pricing discipline while allowing strategic flexibility
A5: STANDARD DISCOUNT SCHEDULE
A6: Scenario | B6: Max Discount | C6: Approval Required | D6: Notes
A7: Annual commitment (vs month-to-month) | B7: 10% | C7: Account Executive | D7: Standard offer — always available
A8: 2-year commitment | B8: 15% | C8: Account Executive
A9: 3-year commitment | B9: 20% | C9: Sales Director
A10: Pilot-to-production conversion | B10: 10% | C10: Account Executive | D10: First year only
A11: Competitive displacement | B11: 15% | C11: Sales Director | D11: Requires documentation
A12: Government / municipal grant-funded | B12: 10% | C12: Account Executive
A13: Bundle discount (3+ add-ons) | B13: 15% | C13: Account Executive | D13: Auto-applied
A14: Nonprofit / tribal agency | B14: 20% | C14: Sales Director | D14: Case-by-case
A15: Strategic / reference account | B15: 25% | C15: VP of Sales | D15: Board approval if >25%
A17: PROTECTED LINE ITEMS (DO NOT HEAVILY DISCOUNT)
A18: Line Item | B18: Why Protected | C18: Guidance
A19: CAD Integration | B19: Significant labor + vendor coordination | C19: Discount max 5% — scope separately
A20: Custom Development | B20: High labor cost | C20: No standard discount — scope per SOW
A21: Onsite Services | B21: Travel + staff time | C21: Discount travel separately if needed
A22: Dedicated Support | B22: Named resource commitment | C22: No discount — price is the floor
A24: ⚠ Any discount >25% requires VP of Sales + CFO written approval. Never quote below floor without authorization.
A25: RULE: Discounts reward commitment, scale, and strategic value — not just pressure to close.

Sheet RC Campus
A1: NEXCORT IQ — INTERNAL PRICING GUIDE
A2: NEXCORT IQ CAMPUS
A3: Universities · Colleges · K-12 · Campus safety reporting · QR/NFC · Anonymous & identified reporting · Clery documentation
A5: BASE SUBSCRIPTION — PER-STUDENT ANNUAL PRICING
A6: Item | B6: Rate | C6: Notes
A7: Annual Rate | B7: $1.40 per enrolled student / year | C7: Based on total institutional enrollment. 30% non-user adjustment already applied.
