Workbook

Sheet Cover
A1: NEXCORT IQ
A2: INTERNAL PRICING GUIDE — CONFIDENTIAL
A3: Intelligence at the Speed of Response
A6: HOW TO USE THIS GUIDE
A7: Public-facing language: | B7: "Tailored deployment" · "Custom quote" · "Scaled for agency needs" · "Contact sales"
A8: Internal pricing basis: | B8: Agency size · Dispatcher seats · PSAPs / sites · Call volume · CAD complexity · Security requirements · Add-ons · Support level
A9: Color convention: | B9: Blue text = hardcoded input (editable) · Green text = Included · Grey = Limited · Red = Add-on
A10: Discounting: | B10: See Discounting Rules tab — Sales Director approval required for >15% discount
A11: CAD write-back rule: | B11: Do NOT include full CAD write-back in pilot base pricing — scope separately after discovery
A13: SHEET INDEX
A14: Sheet | B14: Description
A15: 1. Essential Plan | B15: Base subscription, overage, capabilities for small agencies
A16: 2. Professional Plan | B16: Growing counties/cities, full feature set, QA included
A17: 3. Command Plan | B17: Large agencies, command center, up to 75 seats
A18: 4. Enterprise & Statewide | B18: Multi-agency, 50–500+ seats, custom programs
A19: 5. CAD Integration | B19: Discovery → coordination → read-only → write-back tiers
A20: 6. AI & Call Intelligence | B20: Triage, confidence scoring, summarization, custom tuning
A21: 7. Transcription & Translation | B21: Enhanced accuracy, diarization, live translation, language packs
A22: 8. Caller Media | B22: SMS, photo upload, video upload, live streaming, redaction
A23: 9. Supervisor & QA | B23: Scorecards, coaching, dashboards, QA rubrics
A24: 10. Incident Command | B24: War rooms, command dashboards, runbooks, stakeholder pages
A25: 11. Reliability & Tech Ops | B25: Monitoring integrations, SLOs, alert correlation, on-call routing
... A32: 18. Discounting Rules | B32: Approval thresholds, discount caps, strategic guidance
A34: ⚠ INTERNAL USE ONLY — Do not share with agencies, prospects, or external parties without Sales Director approval.

Sheet Essential
A1: NEXCORT IQ — INTERNAL PRICING GUIDE
A2: NEXCORT IQ ESSENTIAL
A3: Small municipalities · Single-site PSAPs · Pilot deployments · Up to 10 dispatcher seats
A5: BASE SUBSCRIPTION FEES
A6: Item | B6: Tier 1 Micro | C6: Tier 2 Small | D6: Tier 3 Medium | E6: Tier 4 Large | F6: Range (docx) | G6: Notes
A7: Seats | B7: 1–3 | C7: 4–6 | D7: 7–8 | E7: 9–10 | F7: 1–10
A8: Call Volume / Month | B8: <2,000 | C8: 2K–3.5K | D8: 3.5K–4.5K | E8: 4.5K–5K | F8: Varies
A9: Monthly Fee | B9: 2800 | C9: 4200 | D9: 5400 | E9: 6000 | F9: $3,500–$7,500 | G9: Inputs in blue
A10: Annual Fee | B10: =B8*12 | C10: =C8*12 | D10: =D8*12 | E10: =E8*12 | F10: $42K–$90K | G10: Auto-calculated
A11: Recommended Pilot (90-day) | B11: 25000 | C11: 30000 | D11: 37500 | E11: 50000 | F11: $25K–$50K
A12: Setup / Implementation | B12: 10000 | C12: 15000 | D12: 20000 | E12: 25000 | F12: $10K–$25K | G12: One-time
A14: SEAT OVERAGE PRICING
A15: Seat Type | B15: Included in Base | C15: Overage Rate / Month | D15: Notes
A16: Dispatcher Seats | B16: Up to 10 | C16: $150 / seat / month | D16: Seats 11+
A17: Admin / Supervisor Seats | B17: Up to 3 | C17: $100 / seat / month | D17: Seats 4+
A19: INCLUDED CAPABILITIES
A20: Capability | B20: Included? | C20: Notes
A21: Web Application Access | B21: Yes
A22: Desktop Application Access | B22: Yes | C22: Windows & Mac
A23: Role-Based Access Control (RBAC) | B23: Yes
A24: Agency Admin Console | B24: Yes
A25: Core Reporting | B25: Yes
A26: Audit Logs | B26: Yes | C26: CJIS-aware retention
A27: AI-Assisted Intake | B27: Yes
A28: Live Transcription | B28: Yes
A29: Call Triage Workflows | B29: Yes
A30: Call / Session History | B30: Yes
A31: Active Incident View | B31: Yes
A32: Dispatcher Console | B32: Limited | C32: Full in Professional+
A33: Multilingual Intake | B33: Limited | C33: Upgrade for full translation
A34: Language Auto-Detection | B34: Limited
A35: QA Review Tools | B35: Limited | C35: Upgrade for full QA suite
A36: Incident Timeline Reconstruction | B36: Limited
A37: Standard Onboarding | B37: Yes
A38: Integration Assistance | B38: Limited
A40: ESSENTIAL ADD-ON CANDIDATES
A41: Add-On | B41: Price Low / Month | C41: Price High / Month | D41: Notes
A42: Live Translation | B42: 1000 | C42: 3000
A43: Text-to-Voice Support | B43: 750 | C43: 2500
A44: Caller Photo Upload | B44: 500 | C44: 1500
...

Sheet Professional
A1: NEXCORT IQ — INTERNAL PRICING GUIDE
A2: NEXCORT IQ PROFESSIONAL
A3: Growing counties & cities · Full features · Translation · QA · Analytics · Up to 25 dispatcher seats
A5: BASE SUBSCRIPTION FEES
A6: Item | B6: Small Pro T1 | C6: Medium Pro T2 | D6: Large Pro T3 | E6: Max Pro T4 | F6: Range (docx) | G6: Notes
A7: Seats | B7: 1–10 | C7: 11–18 | D7: 19–23 | E7: 24–25 | F7: 1–25
A8: Call Volume / Month | B8: <10,000 | C8: 10K–18K | D8: 18K–23K | E8: 23K–25K | F8: Varies
A9: Monthly Fee | B9: 8500 | C9: 13000 | D9: 15500 | E9: 18000 | F9: $8,500–$18,000
A10: Annual Fee | B10: =B8*12 | C10: =C8*12 | D10: =D8*12 | E10: =E8*12 | F10: $102K–$216K | G10: Auto-calculated
A11: Recommended Pilot (90-day) | B11: 50000 | C11: 70000 | D11: 87500 | E11: 100000 | F11: $50K–$100K
A12: Setup / Implementation | B12: 25000 | C12: 40000 | D12: 50000 | E12: 60000 | F12: $25K–$60K | G12: One-time
A14: SEAT OVERAGE PRICING
A15: Seat Type | B15: Included in Base | C15: Overage Rate / Month | D15: Notes
A16: Dispatcher Seats | B16: Up to 25 | C16: $125 / seat / month | D16: Seats 26+
A17: Admin / Supervisor Seats | B17: Up to 8 | C17: $100 / seat / month | D17: Seats 9+
A19: INCLUDED CAPABILITIES (ALL ESSENTIAL + THESE)
A20: Capability | B20: Included? | C20: Notes
A21: Full Dispatcher Monitoring Console | B21: Yes
A22: Channel / Talk Group Monitoring | B22: Yes
A23: Non-Emergency Intake Queue | B23: Yes
A24: Backlog and SLA Tracking | B24: Yes
A25: Live Translation | B25: Yes | C25: Included — not add-on
A26: Text-to-Voice Support | B26: Yes
A27: Language Auto-Detection | B27: Yes
A28: Caller Photo Upload | B28: Yes
A29: Caller Video Upload | B29: Yes
A30: Media Audit Trail | B30: Yes
A31: Supervisor QA Tools | B31: Yes
A32: Scorecards | B32: Yes
A33: Coaching Notes | B33: Yes
A34: Team Performance Dashboards | B34: Yes
A35: Call Quality Trends | B35: Yes
A36: Incident Timeline Reconstruction | B36: Yes
A37: Post-Incident Reviews | B37: Yes
A38: Integration Assistance | B38: Yes
A39: Priority Support | B39: Yes | C39: Included
A41: LIMITED / ADD-ON IN PROFESSIONAL
A42: Capability | B42: Status | C42: Price Low / Month | D42: Price High / Month | E42: Notes
A43: Live Caller Media Streaming | B43: Limited | C43: 2500 | D43: 6000 | E43: WebRTC real-time
A44: Runbooks / Playbooks | B44: Limited | C44: 1500 | D44: 4000
...

Sheet Command
A1: NEXCORT IQ — INTERNAL PRICING GUIDE
A2: NEXCORT IQ COMMAND
A3: Large agencies · Regional command environments · Major incident coordination · Up to 75 dispatcher seats
A5: BASE SUBSCRIPTION FEES
A6: Item | B6: Small Cmd T1 | C6: Medium Cmd T2 | D6: Large Cmd T3 | E6: Max Cmd T4 | F6: Range (docx) | G6: Notes
A7: Seats | B7: 1–25 | C7: 26–50 | D7: 51–65 | E7: 66–75 | F7: 1–75
A8: Call Volume / Month | B8: <30,000 | C8: 30K–60K | D8: 60K–85K | E8: 85K–100K | F8: Varies
A9: Monthly Fee | B9: 22500 | C9: 31000 | D9: 40000 | E9: 50000 | F9: $22,500–$50,000
A10: Annual Fee | B10: =B8*12 | C10: =C8*12 | D10: =D8*12 | E10: =E8*12 | F10: $270K–$600K | G10: Auto-calculated
A11: Recommended Pilot (90–180 days) | B11: 100000 | C11: 150000 | D11: 200000 | E11: 250000 | F11: $100K–$250K | G11: 6-month standard
A12: Setup / Implementation | B12: 75000 | C12: 100000 | D12: 125000 | E12: 150000 | F12: $75K–$150K | G12: One-time
A14: SEAT OVERAGE PRICING
A15: Seat Type | B15: Included | C15: Overage Rate / Month | D15: Notes
A16: Dispatcher Seats | B16: Up to 75 | C16: $100 / seat / month | D16: Seats 76+
A17: Admin / Supervisor / Command Seats | B17: Up to 20 | C17: $85 / seat / month | D17: Seats 21+
A19: INCLUDED CAPABILITIES (ALL PROFESSIONAL + THESE)
A20: Capability | B20: Included? | C20: Notes
A21: Major Incident Management | B21: Yes
A22: Command Dashboard | B22: Yes
A23: War Rooms | B23: Yes
A24: Runbooks / Playbooks | B24: Yes
A25: Post-Incident Review Tools | B25: Yes
A26: Stakeholder Status Pages | B26: Yes
A27: Monitoring Integrations | B27: Yes
A28: Alert Correlation | B28: Yes
A29: Escalation Engine | B29: Yes
A30: On-Call Routing | B30: Yes
A31: SLO Dashboards | B31: Yes
A32: Reliability Reporting | B32: Yes
... A34: Dedicated Rollout Planning | B34: Yes
A36: LIMITED / ADD-ON IN COMMAND
A37: Capability | B37: Status | C37: Price Low | D37: Price High | E37: Type | F37: Notes
A38: Multi-Site Deployment Support | B38: Limited | C38: 25000 | D38: 100000 | E38: One-time
A39: Custom Security / Compliance Review | B39: Limited | C39: 15000 | D39: 75000 | E39: One-time
A40: Custom CAD Connector | B40: Add-on | C40: 50000 | D40: 250000 | E40: One-time
A41: Dedicated Support Engineer | B41: Add-on | C41: 8000 | D41: 20000 | E41: / month
A42: Onsite Quarterly Review | B42: Add-on | C42: 7500 | D42: 20000 | E42: Per visit
A43: Advanced Data Retention Architecture | B43: Add-on | C43: 10000 | D43: 75000 | E43: One-time
A45: SALES POSITIONING — Command Plan
A46: Best for proving value during high-complexity incidents and cross-team response.
...

Sheet Enterprise
A1: NEXCORT IQ — INTERNAL PRICING GUIDE
A2: ENTERPRISE / STATEWIDE
A3: Multi-agency · 50–500+ seats · Statewide programs · Custom architecture · Dedicated infrastructure
A5: BASE SUBSCRIPTION FEES
A6: Deployment Size | B6: Agencies | C6: Seats | D6: Monthly Fee Range | E6: Annual Fee Range | F6: Notes
A7: Small Enterprise | B7: 2–5 | C7: 50–150 | D7: $60K–$100K / month | E7: $720K–$1.2M / year
A8: Medium Enterprise | B8: 6–15 | C8: 150–300 | D8: $100K–$175K / month | E8: $1.2M–$2.1M / year
A9: Large Enterprise | B9: 16–30 | C9: 300–500 | D9: $175K–$250K / month | E9: $2.1M–$3M / year
A10: Statewide | B10: 30+ | C10: 500+ | D10: $250K+ / month | E10: $3M–$10M+ / year | F10: Custom contract
A12: SEAT OVERAGE
A13: Seat Type | B13: Overage Rate | C13: Notes
A14: Dispatcher Seats | B14: $75–$100 / seat / month | C14: Negotiated per contract
A15: Admin / Supervisor Seats | B15: Custom | C15: Per SOW
A17: SETUP & IMPLEMENTATION
A18: Item | B18: Low | C18: High | D18: Notes
A19: Setup / Implementation | B19: 150000 | C19: 750000 | D19: Per SOW — wide range
A20: Multi-Site Deployment Support | B20: 25000 | C20: 100000 | D20: One-time per scope
A21: Custom Security / Compliance Review | B21: 15000 | C21: 75000 | D21: One-time
A22: Advanced Rollout Services | B22: Custom | C22: Custom | D22: SOW required
A24: INCLUDED CAPABILITIES
A25: Capability | B25: Included? | C25: Notes
A26: All Command capabilities (as applicable) | B26: Yes
A27: Multi-Agency Architecture | B27: Yes
A28: Multi-Site Deployment Planning | B28: Yes
A29: Custom Integrations | B29: Yes | C29: Per SOW
A30: Custom Retention / Security Options | B30: Yes
A31: Advanced Rollout Services | B31: Yes
A32: Procurement and Compliance Support | B32: Yes
A33: Tailored Deployment Architecture | B33: Yes
A34: Dedicated Architecture Planning | B34: Yes
A35: Executive Reporting | B35: Yes
A36: Custom SOW | B36: Yes
A38: SALES POSITIONING — Enterprise / Statewide
A39: Best sales angle: NexCort iQ becomes a long-term public safety modernization platform.
A40: Strong fit for grant-funded programs, large procurements, and regional emergency management transformation.
A41: Every Enterprise deal requires a custom SOW — do not quote fixed prices without Sales Director sign-off.
A42: ⚠ INTERNAL USE ONLY — Enterprise pricing requires VP Sales + Sales Director approval before quoting.

Sheet CAD Integration
A1: NEXCORT IQ — INTERNAL PRICING GUIDE
A2: CAD INTEGRATION ADD-ONS
A3: One-time fees · Complexity-tiered · NexCort iQ enhances CAD — it does not replace it
A5: DISCOVERY & PLANNING
A6: Service | B6: Price Low | C6: Price High | D6: Notes
A7: Basic CAD Discovery Workshop | B7: 7500 | C7: 7500 | D7: Single CAD, standard environment
A8: Standard CAD Discovery Workshop | B8: 10000 | C8: 10000 | D8: Recommended starting point
A9: Advanced CAD Discovery Workshop | B9: 15000 | C9: 15000 | D9: Complex multi-CAD environments
A10: CAD Field Mapping Document | B10: 7500 | C10: 20000
A11: CAD Integration Audit Logging Package | B11: 10000 | C11: 35000
A12: CAD Rollback and Failover Planning | B12: 10000 | C12: 30000
A14: CAD VENDOR COORDINATION
A15: Tier | B15: Price | C15: Description
A16: Basic Vendor Coordination | B16: 10000 | C16: Single CAD vendor, standard API
A17: Standard Vendor Coordination | B17: 17500 | C17: Moderate complexity
A18: Premium Vendor Coordination | B18: 25000 | C18: Multi-vendor or legacy CAD
A19: CAD Sandbox Testing Package | B19: 15000 | C19: Included or $15K–$50K depending on scope
A21: READ-ONLY INTEGRATION
A22: Complexity Tier | B22: One-Time Fee | C22: Description
A23: Tier 1 — Simple | B23: 35000 | C23: Standard REST or webhook
A24: Tier 2 — Standard | B24: 55000 | C24: Moderate mapping / transform
A25: Tier 3 — Complex | B25: 75000 | C25: Legacy protocol / custom adapter
A26: Tier 4 — Advanced | B26: 100000 | C26: Multi-system / real-time
A28: ASSISTED WRITE-BACK INTEGRATION
A29: Complexity Tier | B29: One-Time Fee | C29: Description
A30: Tier 1 — Simple | B30: 75000 | C30: Basic write-back with confirmation
A31: Tier 2 — Standard | B31: 125000 | C31: Standard bidirectional
A32: Tier 3 — Complex | B32: 175000 | C32: Complex data mapping
A33: Tier 4 — Advanced | B33: 250000 | C33: Full bidirectional + validation
A35: AUTOMATED WRITE-BACK INTEGRATION
A36: Complexity Tier | B36: One-Time Fee | C36: Description
A37: Tier 1 — Simple | B37: 150000 | C37: Automated rules-based write-back
A38: Tier 2 — Standard | B38: 250000 | C38: Full automation with logging
A39: Tier 3 — Complex | B39: 375000 | C39: Complex event-driven automation
A40: Tier 4 — Advanced | B40: 500000 | C40: Custom AI-assisted write-back
A42: ADDITIONAL CAD CONNECTORS
A43: Item | B43: Low | C43: High | D43: Notes
A44: Additional CAD Vendor Connector | B44: 75000 | C44: 300000 | D44: Per connector — one-time
A46: RULE: Do NOT include full CAD write-back in pilot base pricing. Scope separately after discovery, sandbox testing, and vendor validation.
A47: Annual maintenance on integrations: 15–20% of integration fee, billed separately.

Sheet AI Intelligence
A1: NEXCORT IQ — INTERNAL PRICING GUIDE
A2: AI & CALL INTELLIGENCE ADD-ONS
A3: Triage workflows · Confidence scoring · Model redundancy · Summarization · Custom tuning
A5: AI TRIAGE WORKFLOWS
A6: Tier | B6: Rules / Coverage | C6: Monthly Fee | D6: Notes
A7: Basic | B7: 5–10 custom rules | C7: 2500 | D7: Single emergency type
A8: Standard | B8: 10–25 rules, 3–5 types | C8: 5000 | D8: Most agencies — recommended
A9: Premium | B9: 25+ rules, all types | C9: 7500 | D9: Full coverage
A11: AI MODEL REDUNDANCY
A12: Level | B12: Monthly Fee Low | C12: Monthly Fee High | D12: Notes
A13: Secondary AI Model Review | B13: 2000 | C13: 6000 | D13: By volume
A14: Tertiary AI Model Fallback | B14: 2000 | C14: 6000 | D14: Adds resilience — recommended for Command+
A16: AI CONFIDENCE & SCORING
A17: Tier | B17: Monthly Fee | C17: Notes
A18: Basic Confidence Scoring | B18: 1500
A19: Advanced Confidence Scoring | B19: 3500
A20: Premium Multi-Factor Scoring | B20: 5000 | C20: Recommended for Command+
A21: AI QA Scoring Model | B21: 2500
A23: AI INCIDENT SUMMARIZATION
A24: Volume Tier | B24: Monthly Fee | C24: Notes
A25: Basic (<5K calls/month) | B25: 1500
A26: Standard (5K–20K calls/month) | B26: 3500
A27: Premium (20K+ calls/month) | B27: 5000
A29: AI CUSTOM DEVELOPMENT & TUNING
A30: Item | B30: Price Low | C30: Price High | D30: Type | E30: Notes
A31: AI Dispatcher Recommendation Engine | B31: 2500 | C31: 10000 | D31: / month
A32: Custom Agency AI Prompts / Playbooks | B32: 10000 | C32: 50000 | D32: One-time
A33: Custom Emergency-Type Workflow Tuning | B33: 5000 | C33: 25000 | D33: Per workflow
A34: AI Post-Incident Review Package | B34: 2500 | C34: 10000 | D34: / month
A36: SALES POSITIONING — AI Add-Ons
A37: Position AI as decision support, not a replacement for dispatcher judgment.
A38: Reduces cognitive load and improves consistency during high-pressure calls.
A39: Custom prompts/playbooks are high-value, high-margin — scope carefully.
A40: ⚠ INTERNAL USE ONLY

Sheet Transcription
A1: NEXCORT IQ — INTERNAL PRICING GUIDE
A2: TRANSCRIPTION & TRANSLATION ADD-ONS
A3: Enhanced accuracy · Speaker diarization · Live translation · Language packs · Text-to-voice
A5: ENHANCED TRANSCRIPTION ACCURACY
A6: Volume Tier | B6: Monthly Fee | C6: Notes
A7: Tier 1 (<5K calls/month) | B7: 1500
A8: Tier 2 (5K–15K calls/month) | B8: 3000
A9: Tier 3 (15K+ calls/month) | B9: 5000
A11: SPEAKER SEPARATION (DIARIZATION)
A12: Volume Tier | B12: Monthly Fee | C12: Notes
A13: Tier 1 (<5K calls/month) | B13: 1000
A14: Tier 2 (5K–15K calls/month) | B14: 2500
A15: Tier 3 (15K+ calls/month) | B15: 4000
A17: LIVE TRANSLATION
A18: Tier | B18: Languages / Volume | C18: Monthly Fee | D18: Notes
A19: Tier 1 | B19: 2–3 languages, <2K translations/mo | C19: 2500
A20: Tier 2 | B20: 4–6 languages, 2K–5K translations/mo | C20: 5500
A21: Tier 3 | B21: 7–10 languages, 5K–10K translations/mo | C21: 8000
A22: Tier 4 | B22: 10+ languages, 10K+ translations/mo | C22: 10000 | D22: Custom SLA available
A24: LANGUAGE PACKS & ADDITIONAL SERVICES
A25: Item | B25: Monthly Fee Low | C25: Monthly Fee High | D25: Notes
A26: Multilingual Intake Package | B26: 1500 | C26: 5000
A27: Text-to-Voice Support | B27: 1500 | C27: 5000
A28: Top 10 Language Support Package | B28: 3500 | C28: 12500 | D28: Bundled
A29: Top 15 Language Support Package | B29: 5000 | C29: 18000 | D29: Bundled
A30: Custom Language Package | B30: 1000 | C30: 4000 | D30: Per language / month
A31: Translation Audit Trail | B31: 1000 | C31: 4000
A33: SALES POSITIONING — Transcription & Translation Add-Ons
A34: Supports diverse communities and improves language access during intake.
A35: Helps dispatchers understand callers faster and create more complete incident records.
A36: Live translation is included in Professional+ — upsell language packs for depth.
A37: ⚠ INTERNAL USE ONLY

Sheet Caller Media
A1: NEXCORT IQ — INTERNAL PRICING GUIDE
A2: CALLER TEXT, PHOTO & VIDEO ADD-ONS
A3: SMS links · Photo upload · Video upload · Live streaming · Redaction · Evidence retention
A5: SMS & TEXT
A6: Service | B6: Monthly Fee Low | C6: Monthly Fee High | D6: Notes
A7: Caller SMS Link Generation | B7: 1500 | C7: 5000
A8: Text-Only Emergency Conversation Link | B8: 2000 | C8: 7500 | D8: Async text triage
A10: PHOTO UPLOAD
A11: Tier | B11: Monthly Fee Low | C11: Monthly Fee High | D11: Notes
A12: Basic (<500 photos/mo, 5MB, 30-day retention) | B12: 1000 | C12: 3500
A13: Standard (<2K photos/mo, 10MB, 90-day retention) | B13: 1000 | C13: 3500
A14: Premium (5K+ photos/mo, 25MB, 1-year retention) | B14: 2000 | C14: 4000
A16: VIDEO UPLOAD & LIVE STREAMING
A17: Service | B17: Monthly Fee Low | C17: Monthly Fee High | D17: Notes
A18: Caller Video Upload | B18: 2500 | C18: 8500 | D18: Async upload
A19: Live Caller Video Streaming | B19: 5000 | C19: 20000 | D19: WebRTC · real-time
A20: Media Audit Trail | B20: 1500 | C20: 5000 | D20: Chain-of-custody logging
A21: Evidence Retention Controls | B21: 2500 | C21: 10000
A22: Secure Media Storage Package | B22: 1500 | C22: 7500 | D22: Plus storage overages
A23: Media Redaction Workflow | B23: 5000 | C23: 20000 | D23: High-margin — scope carefully
A24: Large-Volume Media Package | B24: Custom | C24: Custom | D24: Custom quote required
A26: SALES POSITIONING — Caller Media Add-Ons
A27: Gives dispatchers more real-time context before responders arrive.
A28: Useful when callers cannot safely speak or when visual context improves situational awareness.
A29: Supports better documentation through audit trails and evidence retention.
A30: ⚠ INTERNAL USE ONLY

Sheet Supervisor QA
A1: NEXCORT IQ — INTERNAL PRICING GUIDE
A2: SUPERVISOR & QA ADD-ONS
A3: Scorecards · Coaching · Dashboards · QA rubrics · Analytics · AI grading
A5: QA & COACHING MODULES
A6: Module | B6: Monthly Fee Low | C6: Monthly Fee High | D6: Notes
A7: QA Review Tools | B7: 1500 | C7: 5000 | D7: Full suite — replaces Limited in Essential
A8: Dispatcher Scorecards | B8: 1000 | C8: 4000 | D8: Per-call scoring templates
A9: Coaching Notes | B9: 1000 | C9: 4000 | D9: Supervisor annotation layer
A10: Team Performance Dashboards | B10: 2000 | C10: 7500 | D10: Real-time supervisor view
A11: Call Quality Trends | B11: 2000 | C11: 7500 | D11: Trend reporting + export
A12: Supervisor Training Dashboard | B12: 2500 | C12: 10000
A13: AI QA Scoring Model | B13: 2500 | C13: 10000 | D13: AI-assisted grading
A14: Monthly QA Analytics Report | B14: 2500 | C14: 7500
A16: CUSTOM QA DEVELOPMENT
A17: Item | B17: Price Low | C17: Price High | D17: Type | E17: Notes
A18: Custom QA Scoring Rubric | B18: 7500 | C18: 25000 | D18: One-time
A20: BUNDLE: Scorecards + Coaching Notes + Team Dashboards — 15% discount when ordered together.
A21: SALES POSITIONING — Supervisor & QA Add-Ons
A22: Helps supervisors identify training gaps and improve consistency.
A23: Useful for agencies focused on compliance, coaching, and continuous improvement.
A24: Custom QA rubric is a high-value one-time add-on — scope after pilot.
A25: ⚠ INTERNAL USE ONLY

Sheet Incident Command
A1: NEXCORT IQ — INTERNAL PRICING GUIDE
A2: INCIDENT COMMAND & COLLABORATION ADD-ONS
A3: War rooms · Command dashboards · Runbooks · Timelines · Stakeholder pages · EOC support
A5: INCIDENT COMMAND ADD-ONS
A6: Module | B6: Monthly Fee Low | C6: Monthly Fee High | D6: Notes
A7: Major Incident Management | B7: 5000 | C7: 20000 | D7: Included in Command plan
A8: Command Dashboard | B8: 5000 | C8: 20000 | D8: Included in Command plan
A9: War Rooms | B9: 3500 | C9: 15000 | D9: Included in Command plan
A10: Runbooks / Playbooks | B10: 2500 | C10: 12500 | D10: Included in Command plan
A11: Incident Timeline Reconstruction | B11: 2500 | C11: 10000
A12: Post-Incident Reviews | B12: 2500 | C12: 10000
A13: Stakeholder Status Pages | B13: 3500 | C13: 15000
A14: Public Information Officer View | B14: 2500 | C14: 10000
A15: Executive Incident Briefing Module | B15: 3500 | C15: 15000
A17: SALES POSITIONING — Incident Command Add-Ons
A18: Moves agencies from scattered communication to structured incident coordination.
A19: Valuable during storms, active incidents, large events, mutual aid, and EOC activity.
A20: Note: Major incident management and command dashboard are included in Command plan — upsell for Professional agencies.
A21: ⚠ INTERNAL USE ONLY

Sheet Reliability Ops
A1: NEXCORT IQ — INTERNAL PRICING GUIDE
A2: RELIABILITY & TECHNICAL OPERATIONS ADD-ONS
A3: Monitoring · Alert correlation · Escalation · On-call routing · SLOs · CloudWatch
A5: RELIABILITY & MONITORING ADD-ONS
A6: Module | B6: Monthly Fee Low | C6: Monthly Fee High | D6: Notes
A7: Monitoring Integrations | B7: 2500 | C7: 10000 | D7: Included in Command plan
A8: Alert Correlation | B8: 2500 | C8: 10000
A9: Escalation Engine | B9: 2500 | C9: 10000
A10: On-Call Routing | B10: 2500 | C10: 10000
A11: SLO Dashboards | B11: 2000 | C11: 7500
A12: Reliability Reporting | B12: 2000 | C12: 7500
A13: 24/7 Incident Support Upgrade | B13: 7500 | C13: 25000
A15: ONE-TIME RELIABILITY SERVICES
A16: Item | B16: Price Low | C16: Price High | D16: Type | E16: Notes
A17: CloudWatch Dashboard Package | B17: 5000 | C17: 20000 | D17: One-time
A18: Agency-Specific Monitoring Connector | B18: 10000 | C18: 50000 | D18: One-time
A20: SALES POSITIONING — Reliability & Tech Ops Add-Ons
A21: Gives agencies confidence in system uptime and accountability.
A22: Supports technical transparency during mission-critical operations.
A23: Position for agencies with existing NOC/SOC or formal on-call processes.
A24: ⚠ INTERNAL USE ONLY

Sheet Onsite Services
A1: NEXCORT IQ — INTERNAL PRICING GUIDE
A2: ONSITE DEPLOYMENT SERVICES
A3: Discovery · Installation · Go-live support · Floor support · Travel policy
A5: ONSITE SERVICE RATES
A6: Service | B6: Price Low | C6: Price High | D6: Plus Travel? | E6: Notes
A7: Onsite Discovery Visit | B7: 7500 | C7: 15000 | D7: Yes
A8: Onsite Installation Support | B8: 15000 | C8: 35000 | D8: Yes
A9: Onsite Pilot Launch Support | B9: 20000 | C9: 50000 | D9: Yes
A10: Onsite Production Go-Live Support | B10: 35000 | C10: 100000 | D10: Yes | E10: High-value, plan carefully
A11: Onsite CAD / Vendor Integration Workshop | B11: 15000 | C11: 50000 | D11: Yes
A12: Onsite Dispatcher Floor Support | B12: 10000 | C12: 25000 | D12: Yes | E12: Per week
A13: Onsite Executive Briefing | B13: 7500 | C13: 20000 | D13: Yes
A14: Onsite After-Action Review | B14: 10000 | C14: 30000 | D14: Yes
A16: TRAVEL POLICY
A17: Travel Item | B17: Policy | C17: Notes
A18: Airfare | B18: Actual cost | C18: Economy unless >3 hrs
A19: Hotel | B19: Actual cost
A20: Rental Car / Rideshare | B20: Actual cost
A21: Meals / Per Diem | B21: Federal GSA rate or actual | C21: Whichever is lower
A22: Travel Admin Fee | B22: Optional 10% markup | C22: Must be agreed in SOW
A23: Minimum Onsite Billing | B23: 2 days | C23: Applies to all onsite work
A25: SALES POSITIONING — Onsite Services
A26: Reduces rollout risk by putting NexCort iQ experts with agency staff.
A27: Especially valuable for complex workflows, multiple stakeholders, or limited internal IT.
A28: Always scope travel separately — never bundle into a fixed project price without a travel cap clause.
A29: ⚠ INTERNAL USE ONLY

Sheet Training
A1: NEXCORT IQ — INTERNAL PRICING GUIDE
A2: TRAINING PRICING
A3: Remote & onsite · Dispatcher · Supervisor · Admin · Train-the-trainer · Custom
A5: REMOTE TRAINING
A6: Package | B6: Price Low | C6: Price High | D6: Notes
A7: Standard Onboarding | B7: Included | C7: Included | D7: Included in all plans
A8: Remote Admin Training | B8: 2500 | C8: 7500 | D8: Per session
A9: Remote Dispatcher Training | B9: 2500 | C9: 10000 | D9: Per session
A10: Remote Supervisor Training | B10: 3500 | C10: 12500 | D10: Per session
A12: ONSITE TRAINING (plus travel)
A13: Package | B13: Price Low | C13: Price High | D13: Plus Travel? | E13: Notes
A14: Onsite Dispatcher Training | B14: 10000 | C14: 30000 | D14: Yes
A15: Onsite Supervisor Training | B15: 10000 | C15: 30000 | D15: Yes
A17: ADVANCED TRAINING PACKAGES
A18: Package | B18: Price Low | C18: Price High | D18: Notes
A19: Train-the-Trainer Package | B19: 15000 | C19: 50000
A20: Custom Training Materials | B20: 5000 | C20: 20000 | D20: One-time development fee
A21: Annual Refresher Training | B21: 10000 | C21: 50000 | D21: Per year
A23: SALES POSITIONING — Training Pricing
A24: Training protects the agency from workflow confusion and reduces support burden.
A25: Helps teams understand what NexCort iQ does vs. CAD, CPE, SOPs, and AI decision support.
A26: Train-the-Trainer is high-margin and creates internal champions — recommend for Command+.
A27: ⚠ INTERNAL USE ONLY

Sheet Support
A1: NEXCORT IQ — INTERNAL PRICING GUIDE
A2: SUPPORT PACKAGES
A3: Standard · Priority · Mission-Critical · Dedicated
A5: SUPPORT TIERS OVERVIEW
A6: Support Tier | B6: User Range | C6: Monthly Fee | D6: Response SLA | E6: Key Features | F6: Notes
A7: Standard Support | B7: All plans | C7: Included | D7: Business hours | E7: Email + KB + onboarding | F7: Included in base
A8: Priority Support — Small | B8: <25 users | C8: $2,500/mo | D8: 4-hour response | E8: Named contact + monthly review
A9: Priority Support — Medium | B9: 25–75 users | C9: $5,000/mo | D9: 4-hour response | E9: Named contact + monthly review
A10: Priority Support — Large | B10: 75+ users | C10: $7,500/mo | D10: 2-hour response | E10: Named contact + monthly review
A11: Mission-Critical Support | B11: Command+ | C11: Custom | D11: 1-hour response | E11: 24/7 · escalation handling · exec reviews | F11: Recommended for Command+
A13: DEDICATED SUPPORT RESOURCES
A14: Resource | B14: Monthly Fee Low | C14: Monthly Fee High | D14: Notes
A15: Dedicated Support Engineer | B15: 8000 | C15: 20000 | D15: Named engineer, SLA-bound
A16: Customer Success Manager (CSM) | B16: Custom | C16: Custom | D16: Enterprise / statewide accounts
A17: Dedicated Solution Architect | B17: Custom | C17: Custom | D17: Complex integration programs
A18: Dedicated 24/7 Support Team | B18: Custom | C18: Custom | D18: Per contract
A20: SALES POSITIONING — Support Packages
A21: Mission-Critical support recommended for Command, Enterprise, and any agency in active production.
A22: Dedicated support turns NexCort iQ from a software vendor into an operational partner.
A23: Priority support is included in Professional — be clear that Mission-Critical is an upgrade.
A24: ⚠ INTERNAL USE ONLY

Sheet Storage Overages
A1: NEXCORT IQ — INTERNAL PRICING GUIDE
A2: STORAGE, USAGE & OVERAGES
A3: Included limits by plan · Per-unit overage rates · Call volume · Transcription · Media
A5: INCLUDED USAGE BY PLAN
A6: Resource | B6: Essential | C6: Professional | D6: Command | E6: Enterprise | F6: Notes
A7: Storage | B7: 100 GB | C7: 500 GB | D7: 2 TB | E7: Custom | F7: Expandable via add-on
A8: Call Recording Retention | B8: 90 days | C8: 180 days | D8: 1 year | E8: Custom
A9: Transcription Volume | B9: Included | C9: Included | D9: Included | E9: Custom | F9: Volume limits per contract
A10: Translation Requests | B10: Limited | C10: Included | D10: Included | E10: Custom
A11: API Calls / Month | B11: Standard | C11: Standard | D11: High | E11: Custom
A12: Media Storage (photos/video) | B12: Limited | C12: Standard | D12: Enhanced | E12: Custom
A14: OVERAGE RATES
A15: Resource | B15: Overage Rate | C15: Unit | D15: Notes
A16: Additional Storage | B16: 0.08 | C16: per GB / month | D16: S3 standard + margin
A17: Additional Call Volume | B17: 0.003 | C17: per call over limit | D17: Blended AI processing cost
A18: Additional Transcription | B18: 0.01 | C18: per minute over limit
A19: Additional Translation Requests | B19: 0.05 | C19: per request over limit
A20: Additional Photo Storage | B20: 0.05 | C20: per 100 photos over limit
A21: Archive Storage | B21: 0.02 | C21: per GB / month | D21: Cold storage tier
A22: Data Export | B22: 0.1 | C22: per GB exported | D22: Large exports only
A23: High-Volume API Use | B23: Custom | C23: Custom | D23: Negotiate in contract
A25: SALES POSITIONING — Storage & Overages
A26: Overages protect both the agency and NexCort iQ by allowing flexible usage without forcing an immediate plan change.
A27: Useful during storms, major incidents, seasonal spikes, or large-scale emergencies.
A28: Always discuss expected call volumes during discovery to right-size the plan before signing.
A29: ⚠ INTERNAL USE ONLY

Sheet Pilot Programs
A1: NEXCORT IQ — INTERNAL PRICING GUIDE
A2: PILOT PROGRAMS
A3: Pre-packaged pilot bundles for common agency profiles
A5: PILOT PROGRAM OVERVIEW
A6: Program | B6: Duration | C6: Fee Low | D6: Fee High | E6: Typical Scope | F6: Notes
A7: Small City Pilot | B7: 90 days | C7: 20000 | D7: 40000 | E7: Essential + setup + onboarding + training + CAD discovery | F7: Grant-friendly
A8: County Professional Pilot | B8: 90 days | C8: 50000 | D8: 100000 | E8: Professional + translation + caller media + CAD discovery/read-only + training
A9: Command Center Pilot | B9: 90–180 days | C9: 100000 | D9: 250000 | E9: Command + CAD read-only + major incident + war rooms + onsite + training
A10: Enterprise / Statewide Pilot | B10: 6 months | C10: 250000 | D10: 750000 | E10: Enterprise architecture + multi-site + custom integrations + dedicated support | F10: Custom SOW required
A12: SALES POSITIONING — Small City Pilot
A13: Smaller municipalities that want to evaluate NexCort iQ without a full production commitment.
A14: Usually includes Essential-level access, setup, onboarding, training, and CAD discovery.
A15: Sales angle: low-risk, practical way to test value, collect feedback, and support grant-funded modernization.
A17: SALES POSITIONING — County Professional Pilot
A18: Mid-size cities, counties, or regional PSAPs ready for a broader operational test.
A19: Includes Professional-level features: translation, caller media, QA, and supervisor visibility.
A20: Sales angle: demonstrates value across multiple workflows — not just basic AI triage.
A22: SALES POSITIONING — Command Center Pilot
A23: Larger agencies, EOCs, or regional response environments.
A24: May include Command-level tools, war rooms, onsite support, and expanded training.
A25: Sales angle: proves NexCort iQ as a command and coordination platform.
... A32: ⚠ INTERNAL USE ONLY — Pilot pricing to be approved by Sales Director before quoting.

Sheet Quote Builder
A1: NEXCORT IQ
A2: INTERACTIVE QUOTE BUILDER — INTERNAL USE ONLY
A3: 🟡 Yellow = you answer | 🔵 Blue = auto-calculated | See "Client Quote" tab for printable output
B5: Question / Line Item | C5: Category | D5: Your Answer (dropdown) | F5: Std Unit Price | H5: Override Price | J5: Monthly Total
A6: Override Price = leave blank to use standard. Enter a custom value to override for this quote only. Red border = override active.
A7: SECTION 1 — AGENCY PROFILE
A8: 1 | B8: Agency / Department Name
A9: 2 | B9: Contact Name & Title
A10: 3 | B10: Number of Dispatcher Seats
A11: 4 | B11: Number of Admin / Supervisor Seats
A12: 5 | B12: Estimated Call Volume / Month
A14: SECTION 2 — BASE PLAN SELECTION
A15: 6 | B15: Base Plan | F15: =IF(D15="Essential",IF(D10<=3,2800,IF(D10<=6,4200,IF(D10<=8,5400,IF(D10<=10,6000,6000)))),IF(D15="Professional",IF(D10<=10,8500,IF(D10<=18,13000,IF(D10<=23,15500,IF(D10<=25,18000,18000)))),IF(D15="Command",IF(D10<=25,22500,IF(D10<=50,31000,IF(D10<=65,40000,IF(D10<=75,50000,50000)))),IF(D15="Enterprise",80000,0)))) | J15: =IF(ISNUMBER(H15),H15,F15)
A16: 7 | B16: Contract Term | F16: =IF(D16="1-year",0,IF(D16="2-year",0.15,IF(D16="3-year",0.20,0))) | J16: Discount rate — applied in summary
A17: 8 | B17: Dispatcher Seat Overage (auto) | F17: =IF(D15="Essential",150,IF(D15="Professional",125,IF(D15="Command",100,IF(D15="Enterprise",88,0)))) | J17: =IF(ISNUMBER(H17),H17,MAX(0,D10-IF(D15="Essential",10,IF(D15="Professional",25,IF(D15="Command",75,IF(D15="Enterprise",200,0)))))*F17)
A18: 9 | B18: Admin / Supervisor Seat Overage (auto) | F18: =IF(D15="Essential",100,IF(D15="Professional",100,IF(D15="Command",85,IF(D15="Enterprise",90,0)))) | J18: =IF(ISNUMBER(H18),H18,MAX(0,D11-IF(D15="Essential",3,IF(D15="Professional",8,IF(D15="Command",20,IF(D15="Enterprise",30,0)))))*F18)
A19: 10 | B19: Setup & Implementation Fee | F19: =IF(D15="Essential",IF(D10<=3,10000,IF(D10<=6,12500,IF(D10<=8,17500,22500))),IF(D15="Professional",IF(D10<=10,25000,IF(D10<=18,35000,IF(D10<=23,45000,55000))),IF(D15="Command",IF(D10<=25,75000,IF(D10<=50,90000,IF(D10<=65,110000,130000))),IF(D15="Enterprise",200000,0)))) | J19: =IF(ISNUMBER(H19),H19,F19)
A21: =IF(MAX(F16,D22)>0.15,"⚠ DISCOUNT >15% — Sales Director approval required","✓ Discount within standard range")
A22: 11 | B22: Additional Discount Override (0–25%) | F22: =F16 | J22: =MAX(F16,D22)
A24: SECTION 3 — ADD-ON MODULES (all add-ons shown — select None to exclude)
A25: 12 | B25: CAD Integration | F25: =IF(D25="None",0,IF(D25="Discovery Workshop ($7,500)",7500,IF(D25="Discovery Workshop Advanced ($15,000)",15000,IF(D25="Vendor Coordination Basic ($10,000)",10000,IF(D25="Vendor Coordination Premium ($25,000)",25000,IF(D25="Read-Only Tier 1 ($35,000)",35000,IF(D25="Read-Only Tier 2 ($55,000)",55000,IF(D25="Read-Only Tier 3 ($75,000)",75000,IF(D25="Read-Only Tier 4 ($100,000)",100000,IF(D25="Assisted Write-Back T1 ($75,000)",75000,IF(D25="Assisted Write-Back T2 ($125,000)",125000,IF(D25="Assisted Write-Back T3 ($175,000)",175000,IF(D25="Automated Write-Back T1 ($150,000)",150000,IF(D25="Automated Write-Back T2 ($250,000)",250000,0)))))))))))))) | J25: =IF(ISNUMBER(H25),H25,F25)
A26: 13 | B26: AI Triage Workflows | F26: =IF(D26="None",0,IF(D26="Basic 5-10 rules ($2,500/mo)",2500,IF(D26="Standard 10-25 rules ($5,000/mo)",5000,IF(D26="Premium 25+ rules ($7,500/mo)",7500,0)))) | J26: =IF(ISNUMBER(H26),H26,F26)
A27: 14 | B27: AI Confidence Scoring | F27: =IF(D27="None",0,IF(D27="Basic ($1,500/mo)",1500,IF(D27="Advanced ($3,500/mo)",3500,IF(D27="Premium ($5,000/mo)",5000,0)))) | J27: =IF(ISNUMBER(H27),H27,F27)
A28: 15 | B28: AI Incident Summarization | F28: =IF(D28="None",0,IF(D28="Basic <5K calls ($1,500/mo)",1500,IF(D28="Standard 5K-20K calls ($3,500/mo)",3500,IF(D28="Premium 20K+ calls ($5,000/mo)",5000,0)))) | J28: =IF(ISNUMBER(H28),H28,F28)
A29: 16 | B29: AI Dispatcher Recommendation Engine | F29: =IF(D29="None",0,IF(D29="Standard ($2,500/mo)",2500,IF(D29="Advanced ($10,000/mo)",10000,0))) | J29: =IF(ISNUMBER(H29),H29,F29)
A30: 17 | B30: Enhanced Transcription Accuracy | F30: =IF(D30="None",0,IF(D30="Tier 1 <5K calls ($1,500/mo)",1500,IF(D30="Tier 2 5K-15K calls ($3,000/mo)",3000,IF(D30="Tier 3 15K+ calls ($5,000/mo)",5000,0)))) | J30: =IF(ISNUMBER(H30),H30,F30)
A31: 18 | B31: Speaker Diarization | F31: =IF(D31="None",0,IF(D31="Tier 1 <5K ($1,000/mo)",1000,IF(D31="Tier 2 5K-15K ($2,500/mo)",2500,IF(D31="Tier 3 15K+ ($4,000/mo)",4000,0)))) | J31: =IF(ISNUMBER(H31),H31,F31)
A32: 19 | B32: Live Translation | F32: =IF(OR(D32="None (included Pro+)",D32="None"),0,IF(D32="Tier 1 2-3 languages ($2,500/mo)",2500,IF(D32="Tier 2 4-6 languages ($5,500/mo)",5500,IF(D32="Tier 3 7-10 languages ($8,000/mo)",8000,IF(D32="Tier 4 10+ languages ($10,000/mo)",10000,0))))) | J32: =IF(D15="Essential",IF(ISNUMBER(H32),H32,F32),0)
A33: 20 | B33: Language Packs (Top 10 Languages) | F33: =IF(D33="None",0,IF(D33="Top 10 Languages ($3,500/mo)",3500,IF(D33="Top 15 Languages ($5,000/mo)",5000,0))) | J33: =IF(ISNUMBER(H33),H33,F33)
A34: 21 | B34: Caller SMS Link Generation | F34: =IF(D34="None",0,IF(D34="Basic <500 links ($1,500/mo)",1500,IF(D34="Standard ($5,000/mo)",5000,0))) | J34: =IF(ISNUMBER(H34),H34,F34)
A35: 22 | B35: Caller Photo Upload | F35: =IF(D35="None",0,IF(D35="Basic 500 photos ($1,000/mo)",1000,IF(D35="Standard 2K photos ($2,500/mo)",2500,IF(D35="Premium 5K+ photos ($4,000/mo)",4000,0)))) | J35: =IF(ISNUMBER(H35),H35,F35)
A36: 23 | B36: Caller Video Upload | F36: =IF(D36="None",0,IF(D36="Standard ($2,500/mo)",2500,IF(D36="Premium ($8,500/mo)",8500,0))) | J36: =IF(ISNUMBER(H36),H36,F36)
A37: 24 | B37: Live Caller Video Streaming | F37: =IF(D37="None",0,IF(D37="Standard ($5,000/mo)",5000,IF(D37="Premium ($20,000/mo)",20000,0))) | J37: =IF(ISNUMBER(H37),H37,F37)
A38: 25 | B38: Media Audit Trail & Redaction | F38: =IF(D38="None",0,IF(D38="Audit Trail ($1,500/mo)",1500,IF(D38="Audit + Redaction ($7,500/mo)",7500,0))) | J38: =IF(ISNUMBER(H38),H38,F38)
A39: 26 | B39: QA Review Tools | F39: =IF(OR(D39="None (included Pro+)",D39="None"),0,IF(D39="Basic Scorecards ($1,000/mo)",1000,IF(D39="Full QA Suite ($3,500/mo)",3500,IF(D39="QA Suite + AI Grading ($6,000/mo)",6000,0)))) | J39: =IF(D15="Essential",IF(ISNUMBER(H39),H39,F39),0)
A40: 27 | B40: Team Performance Dashboards | F40: =IF(OR(D40="None (included Pro+)",D40="None"),0,IF(D40="Standard ($2,000/mo)",2000,IF(D40="Advanced ($7,500/mo)",7500,0))) | J40: =IF(D15="Essential",IF(ISNUMBER(H40),H40,F40),0)
A41: 28 | B41: Incident Command Suite | F41: =IF(OR(D41="None (included Command+)",D41="None"),0,IF(D41="Basic Package ($5,000/mo)",5000,IF(D41="Full Command Suite ($12,500/mo)",12500,0))) | J41: =IF(OR(D15="Essential",D15="Professional"),IF(ISNUMBER(H41),H41,F41),0)
A42: 29 | B42: Reliability & Tech Ops | F42: =IF(OR(D42="None (included Command+)",D42="None"),0,IF(D42="Basic Monitoring ($2,500/mo)",2500,IF(D42="Full Reliability Suite ($7,500/mo)",7500,0))) | J42: =IF(OR(D15="Essential",D15="Professional"),IF(ISNUMBER(H42),H42,F42),0)
A43: 30 | B43: Support Package | F43: =IF(OR(D43="Standard (Included)",D43=""),0,IF(D43="Priority Small <25 users ($2,500/mo)",2500,IF(D43="Priority Medium 25-75 ($5,000/mo)",5000,IF(D43="Priority Large 75+ ($7,500/mo)",7500,0)))) | J43: =IF(D15="Essential",IF(ISNUMBER(H43),H43,F43),0)
A44: 31 | B44: Onsite Services | F44: =IF(D44="None",0,IF(D44="Discovery Visit ($10,000)",10000,IF(D44="Pilot Launch Support ($35,000)",35000,IF(D44="Go-Live Support ($65,000)",65000,IF(D44="Full Program ($100,000)",100000,0))))) | J44: =IF(ISNUMBER(H44),H44,F44)
...

Sheet Client Quote
D1: NEXCORT IQ
A5: Apps on Demand LLC d/b/a NexCort iQ | Intelligence at the Speed of Response
A7: ='Quote Builder'!D8&" — Service Proposal"
A8: ='Quote Builder'!D9
A10: QUOTE DETAILS
A11: Plan Selected | F11: ='Quote Builder'!D15
A12: Contract Term | F12: ='Quote Builder'!D16
A13: Dispatcher Seats | F13: ='Quote Builder'!D10
A14: Admin / Supervisor Seats | F14: ='Quote Builder'!D11
A15: Est. Call Volume / Month | F15: ='Quote Builder'!D12&" calls"
A16: Quote Prepared | F16: =TODAY()
A18: PRICING BREAKDOWN
A19: # | B19: Description | F19: Monthly ($) | H19: One-Time / Annual ($)
A20: 1 | B20: ="Base Plan — "&'Quote Builder'!D15&" ("&'Quote Builder'!D10&" dispatcher seats)" | F20: ='Quote Builder'!J15 | H20: ='Quote Builder'!J15*12
A21: 2 | B21: Dispatcher Seat Overage | F21: =IF('Quote Builder'!J17>0,'Quote Builder'!J17,"—") | H21: =IF('Quote Builder'!J17>0,'Quote Builder'!J17*12,"—")
A22: 3 | B22: Admin / Supervisor Seat Overage | F22: =IF('Quote Builder'!J18>0,'Quote Builder'!J18,"—") | H22: =IF('Quote Builder'!J18>0,'Quote Builder'!J18*12,"—")
A23: 4 | B23: Setup & Implementation Fee | F23: — | H23: ='Quote Builder'!J19
A24: ADD-ON MODULES
A25: 5 | B25: CAD Integration | F25: =IF('Quote Builder'!J25>0,'Quote Builder'!J25,"—") | H25: =IF('Quote Builder'!J25>0,'Quote Builder'!J25*12,"—")
A26: 6 | B26: AI Triage Workflows | F26: =IF('Quote Builder'!J26>0,'Quote Builder'!J26,"—") | H26: =IF('Quote Builder'!J26>0,'Quote Builder'!J26*12,"—")
A27: 7 | B27: AI Confidence Scoring | F27: =IF('Quote Builder'!J27>0,'Quote Builder'!J27,"—") | H27: =IF('Quote Builder'!J27>0,'Quote Builder'!J27*12,"—")
A28: 8 | B28: AI Incident Summarization | F28: =IF('Quote Builder'!J28>0,'Quote Builder'!J28,"—") | H28: =IF('Quote Builder'!J28>0,'Quote Builder'!J28*12,"—")
A29: 9 | B29: AI Dispatcher Recommendation Engine | F29: =IF('Quote Builder'!J29>0,'Quote Builder'!J29,"—") | H29: =IF('Quote Builder'!J29>0,'Quote Builder'!J29*12,"—")
A30: 10 | B30: Enhanced Transcription Accuracy | F30: =IF('Quote Builder'!J30>0,'Quote Builder'!J30,"—") | H30: =IF('Quote Builder'!J30>0,'Quote Builder'!J30*12,"—")
A31: 11 | B31: Speaker Diarization | F31: =IF('Quote Builder'!J31>0,'Quote Builder'!J31,"—") | H31: =IF('Quote Builder'!J31>0,'Quote Builder'!J31*12,"—")
A32: 12 | B32: Live Translation | F32: =IF('Quote Builder'!J32>0,'Quote Builder'!J32,"—") | H32: =IF('Quote Builder'!J32>0,'Quote Builder'!J32*12,"—")
A33: 13 | B33: Language Packs | F33: =IF('Quote Builder'!J33>0,'Quote Builder'!J33,"—") | H33: =IF('Quote Builder'!J33>0,'Quote Builder'!J33*12,"—")
A34: 14 | B34: Caller SMS Link Generation | F34: =IF('Quote Builder'!J34>0,'Quote Builder'!J34,"—") | H34: =IF('Quote Builder'!J34>0,'Quote Builder'!J34*12,"—")
A35: 15 | B35: Caller Photo Upload | F35: =IF('Quote Builder'!J35>0,'Quote Builder'!J35,"—") | H35: =IF('Quote Builder'!J35>0,'Quote Builder'!J35*12,"—")
A36: 16 | B36: Caller Video Upload | F36: =IF('Quote Builder'!J36>0,'Quote Builder'!J36,"—") | H36: =IF('Quote Builder'!J36>0,'Quote Builder'!J36*12,"—")
... A43: 23 | B43: Support Package Upgrade | F43: =IF('Quote Builder'!J43>0,'Quote Builder'!J43,"—") | H43: =IF('Quote Builder'!J43>0,'Quote Builder'!J43*12,"—")
A44: 24 | B44: Onsite Services | F44: — | H44: =IF('Quote Builder'!J44>0,'Quote Builder'!J44,"—")
A45: 25 | B45: Training Package | F45: — | H45: =IF('Quote Builder'!J45>0,'Quote Builder'!J45,"—")
B47: Subtotal — Monthly Recurring | F47: ='Quote Builder'!J15+'Quote Builder'!J17+'Quote Builder'!J18+SUMPRODUCT(('Quote Builder'!J25:J43)*1) | H47: =('Quote Builder'!J15+'Quote Builder'!J17+'Quote Builder'!J18+SUMPRODUCT(('Quote Builder'!J25:J43)*1))*12
B48: Subtotal — One-Time Fees | F48: — | H48: ='Quote Builder'!J19+'Quote Builder'!J25+'Quote Builder'!J44+'Quote Builder'!J45
B49: =IF(MAX('Quote Builder'!F16,'Quote Builder'!D22)>0,"Discount ("&TEXT(MAX('Quote Builder'!F16,'Quote Builder'!D22),"0%")&") Applied","No Discount") | F49: =IFERROR(-F47*MAX('Quote Builder'!F16,'Quote Builder'!D22),0) | H49: =IFERROR(-I48*MAX('Quote Builder'!F16,'Quote Builder'!D22),0)
B51: ★ TOTAL MONTHLY | F51: =F47+F49 | H51: =(F47+F49)*12
B52: ★ TOTAL ONE-TIME FEES | F52: — | H52: =I48+I49
B53: ★ ESTIMATED ANNUAL INVESTMENT | F53: — | H53: =(F47+F49)*12+(I48+I49)
A55: TERMS & NEXT STEPS
...

Sheet Discounting
A1: NEXCORT IQ — INTERNAL PRICING GUIDE
A2: DISCOUNTING RULES
A3: Internal — protect pricing discipline while allowing strategic flexibility
A5: STANDARD DISCOUNT SCHEDULE
A6: Scenario | B6: Max Discount | C6: Approval Required | D6: Notes
A7: Annual commitment (vs month-to-month) | B7: 10% | C7: Account Executive | D7: Standard offer — always available
A8: 2-year commitment | B8: 15% | C8: Account Executive
A9: 3-year commitment | B9: 20% | C9: Sales Director
A10: Pilot-to-production conversion | B10: 10% | C10: Account Executive | D10: First year only
A11: Competitive displacement | B11: 15% | C11: Sales Director | D11: Requires documentation
A12: Government / municipal grant-funded | B12: 10% | C12: Account Executive
A13: Bundle discount (3+ add-ons) | B13: 15% | C13: Account Executive | D13: Auto-applied
A14: Nonprofit / tribal agency | B14: 20% | C14: Sales Director | D14: Case-by-case
A15: Strategic / reference account | B15: 25% | C15: VP of Sales | D15: Board approval if >25%
A17: PROTECTED LINE ITEMS (DO NOT HEAVILY DISCOUNT)
A18: Line Item | B18: Why Protected | C18: Guidance
A19: CAD Integration | B19: Significant labor + vendor coordination | C19: Discount max 5% — scope separately
A20: Custom Development | B20: High labor cost | C20: No standard discount — scope per SOW
A21: Onsite Services | B21: Travel + staff time | C21: Discount travel separately if needed
A22: Dedicated Support | B22: Named resource commitment | C22: No discount — price is the floor
A24: ⚠ Any discount >25% requires VP of Sales + CFO written approval. Never quote below floor without authorization.
A25: RULE: Discounts reward commitment, scale, and strategic value — not just pressure to close.
